
2020-01-05 17:12:53,226 INFO: errors [in /Users/eiji/Desktop/class-demo/01_fyyur/projects/app.py:534]
2020-01-05 17:12:59,558 ERROR: Exception on /venues [GET] [in /Users/eiji/anaconda3/lib/python3.7/site-packages/flask/app.py:1780]
Traceback (most recent call last):
  File "/Users/eiji/anaconda3/lib/python3.7/site-packages/sqlalchemy/engine/base.py", line 2276, in _wrap_pool_connect
    return fn()
  File "/Users/eiji/anaconda3/lib/python3.7/site-packages/sqlalchemy/pool/base.py", line 363, in connect
    return _ConnectionFairy._checkout(self)
  File "/Users/eiji/anaconda3/lib/python3.7/site-packages/sqlalchemy/pool/base.py", line 760, in _checkout
    fairy = _ConnectionRecord.checkout(pool)
  File "/Users/eiji/anaconda3/lib/python3.7/site-packages/sqlalchemy/pool/base.py", line 492, in checkout
    rec = pool._do_get()
  File "/Users/eiji/anaconda3/lib/python3.7/site-packages/sqlalchemy/pool/impl.py", line 139, in _do_get
    self._dec_overflow()
  File "/Users/eiji/anaconda3/lib/python3.7/site-packages/sqlalchemy/util/langhelpers.py", line 68, in __exit__
    compat.reraise(exc_type, exc_value, exc_tb)
  File "/Users/eiji/anaconda3/lib/python3.7/site-packages/sqlalchemy/util/compat.py", line 153, in reraise
    raise value
  File "/Users/eiji/anaconda3/lib/python3.7/site-packages/sqlalchemy/pool/impl.py", line 136, in _do_get
    return self._create_connection()
  File "/Users/eiji/anaconda3/lib/python3.7/site-packages/sqlalchemy/pool/base.py", line 308, in _create_connection
    return _ConnectionRecord(self)
  File "/Users/eiji/anaconda3/lib/python3.7/site-packages/sqlalchemy/pool/base.py", line 437, in __init__
    self.__connect(first_connect_check=True)
  File "/Users/eiji/anaconda3/lib/python3.7/site-packages/sqlalchemy/pool/base.py", line 639, in __connect
    connection = pool._invoke_creator(self)
  File "/Users/eiji/anaconda3/lib/python3.7/site-packages/sqlalchemy/engine/strategies.py", line 114, in connect
    return dialect.connect(*cargs, **cparams)
  File "/Users/eiji/anaconda3/lib/python3.7/site-packages/sqlalchemy/engine/default.py", line 482, in connect
    return self.dbapi.connect(*cargs, **cparams)
  File "/Users/eiji/anaconda3/lib/python3.7/site-packages/psycopg2/__init__.py", line 126, in connect
    conn = _connect(dsn, connection_factory=connection_factory, **kwasync)
psycopg2.OperationalError: FATAL:  role "amy" does not exist


The above exception was the direct cause of the following exception:

Traceback (most recent call last):
  File "/Users/eiji/anaconda3/lib/python3.7/site-packages/flask/app.py", line 2311, in wsgi_app
    response = self.full_dispatch_request()
  File "/Users/eiji/anaconda3/lib/python3.7/site-packages/flask/app.py", line 1834, in full_dispatch_request
    rv = self.handle_user_exception(e)
  File "/Users/eiji/anaconda3/lib/python3.7/site-packages/flask/app.py", line 1737, in handle_user_exception
    reraise(exc_type, exc_value, tb)
  File "/Users/eiji/anaconda3/lib/python3.7/site-packages/flask/_compat.py", line 36, in reraise
    raise value
  File "/Users/eiji/anaconda3/lib/python3.7/site-packages/flask/app.py", line 1832, in full_dispatch_request
    rv = self.dispatch_request()
  File "/Users/eiji/anaconda3/lib/python3.7/site-packages/flask/app.py", line 1818, in dispatch_request
    return self.view_functions[rule.endpoint](**req.view_args)
  File "/Users/eiji/Desktop/class-demo/01_fyyur/projects/app.py", line 137, in venues
    areas=Venue.query.all()
  File "/Users/eiji/anaconda3/lib/python3.7/site-packages/sqlalchemy/orm/query.py", line 3211, in all
    return list(self)
  File "/Users/eiji/anaconda3/lib/python3.7/site-packages/sqlalchemy/orm/query.py", line 3367, in __iter__
    return self._execute_and_instances(context)
  File "/Users/eiji/anaconda3/lib/python3.7/site-packages/sqlalchemy/orm/query.py", line 3389, in _execute_and_instances
    querycontext, self._connection_from_session, close_with_result=True
  File "/Users/eiji/anaconda3/lib/python3.7/site-packages/sqlalchemy/orm/query.py", line 3404, in _get_bind_args
    mapper=self._bind_mapper(), clause=querycontext.statement, **kw
  File "/Users/eiji/anaconda3/lib/python3.7/site-packages/sqlalchemy/orm/query.py", line 3382, in _connection_from_session
    conn = self.session.connection(**kw)
  File "/Users/eiji/anaconda3/lib/python3.7/site-packages/sqlalchemy/orm/session.py", line 1124, in connection
    execution_options=execution_options,
  File "/Users/eiji/anaconda3/lib/python3.7/site-packages/sqlalchemy/orm/session.py", line 1130, in _connection_for_bind
    engine, execution_options
  File "/Users/eiji/anaconda3/lib/python3.7/site-packages/sqlalchemy/orm/session.py", line 431, in _connection_for_bind
    conn = bind._contextual_connect()
  File "/Users/eiji/anaconda3/lib/python3.7/site-packages/sqlalchemy/engine/base.py", line 2242, in _contextual_connect
    self._wrap_pool_connect(self.pool.connect, None),
  File "/Users/eiji/anaconda3/lib/python3.7/site-packages/sqlalchemy/engine/base.py", line 2280, in _wrap_pool_connect
    e, dialect, self
  File "/Users/eiji/anaconda3/lib/python3.7/site-packages/sqlalchemy/engine/base.py", line 1547, in _handle_dbapi_exception_noconnection
    util.raise_from_cause(sqlalchemy_exception, exc_info)
  File "/Users/eiji/anaconda3/lib/python3.7/site-packages/sqlalchemy/util/compat.py", line 398, in raise_from_cause
    reraise(type(exception), exception, tb=exc_tb, cause=cause)
  File "/Users/eiji/anaconda3/lib/python3.7/site-packages/sqlalchemy/util/compat.py", line 152, in reraise
    raise value.with_traceback(tb)
  File "/Users/eiji/anaconda3/lib/python3.7/site-packages/sqlalchemy/engine/base.py", line 2276, in _wrap_pool_connect
    return fn()
  File "/Users/eiji/anaconda3/lib/python3.7/site-packages/sqlalchemy/pool/base.py", line 363, in connect
    return _ConnectionFairy._checkout(self)
  File "/Users/eiji/anaconda3/lib/python3.7/site-packages/sqlalchemy/pool/base.py", line 760, in _checkout
    fairy = _ConnectionRecord.checkout(pool)
  File "/Users/eiji/anaconda3/lib/python3.7/site-packages/sqlalchemy/pool/base.py", line 492, in checkout
    rec = pool._do_get()
  File "/Users/eiji/anaconda3/lib/python3.7/site-packages/sqlalchemy/pool/impl.py", line 139, in _do_get
    self._dec_overflow()
  File "/Users/eiji/anaconda3/lib/python3.7/site-packages/sqlalchemy/util/langhelpers.py", line 68, in __exit__
    compat.reraise(exc_type, exc_value, exc_tb)
  File "/Users/eiji/anaconda3/lib/python3.7/site-packages/sqlalchemy/util/compat.py", line 153, in reraise
    raise value
  File "/Users/eiji/anaconda3/lib/python3.7/site-packages/sqlalchemy/pool/impl.py", line 136, in _do_get
    return self._create_connection()
  File "/Users/eiji/anaconda3/lib/python3.7/site-packages/sqlalchemy/pool/base.py", line 308, in _create_connection
    return _ConnectionRecord(self)
  File "/Users/eiji/anaconda3/lib/python3.7/site-packages/sqlalchemy/pool/base.py", line 437, in __init__
    self.__connect(first_connect_check=True)
  File "/Users/eiji/anaconda3/lib/python3.7/site-packages/sqlalchemy/pool/base.py", line 639, in __connect
    connection = pool._invoke_creator(self)
  File "/Users/eiji/anaconda3/lib/python3.7/site-packages/sqlalchemy/engine/strategies.py", line 114, in connect
    return dialect.connect(*cargs, **cparams)
  File "/Users/eiji/anaconda3/lib/python3.7/site-packages/sqlalchemy/engine/default.py", line 482, in connect
    return self.dbapi.connect(*cargs, **cparams)
  File "/Users/eiji/anaconda3/lib/python3.7/site-packages/psycopg2/__init__.py", line 126, in connect
    conn = _connect(dsn, connection_factory=connection_factory, **kwasync)
sqlalchemy.exc.OperationalError: (psycopg2.OperationalError) FATAL:  role "amy" does not exist

(Background on this error at: http://sqlalche.me/e/e3q8)
2020-01-05 17:13:05,565 ERROR: Exception on /venues [GET] [in /Users/eiji/anaconda3/lib/python3.7/site-packages/flask/app.py:1780]
Traceback (most recent call last):
  File "/Users/eiji/anaconda3/lib/python3.7/site-packages/sqlalchemy/engine/base.py", line 2276, in _wrap_pool_connect
    return fn()
  File "/Users/eiji/anaconda3/lib/python3.7/site-packages/sqlalchemy/pool/base.py", line 363, in connect
    return _ConnectionFairy._checkout(self)
  File "/Users/eiji/anaconda3/lib/python3.7/site-packages/sqlalchemy/pool/base.py", line 760, in _checkout
    fairy = _ConnectionRecord.checkout(pool)
  File "/Users/eiji/anaconda3/lib/python3.7/site-packages/sqlalchemy/pool/base.py", line 492, in checkout
    rec = pool._do_get()
  File "/Users/eiji/anaconda3/lib/python3.7/site-packages/sqlalchemy/pool/impl.py", line 139, in _do_get
    self._dec_overflow()
  File "/Users/eiji/anaconda3/lib/python3.7/site-packages/sqlalchemy/util/langhelpers.py", line 68, in __exit__
    compat.reraise(exc_type, exc_value, exc_tb)
  File "/Users/eiji/anaconda3/lib/python3.7/site-packages/sqlalchemy/util/compat.py", line 153, in reraise
    raise value
  File "/Users/eiji/anaconda3/lib/python3.7/site-packages/sqlalchemy/pool/impl.py", line 136, in _do_get
    return self._create_connection()
  File "/Users/eiji/anaconda3/lib/python3.7/site-packages/sqlalchemy/pool/base.py", line 308, in _create_connection
    return _ConnectionRecord(self)
  File "/Users/eiji/anaconda3/lib/python3.7/site-packages/sqlalchemy/pool/base.py", line 437, in __init__
    self.__connect(first_connect_check=True)
  File "/Users/eiji/anaconda3/lib/python3.7/site-packages/sqlalchemy/pool/base.py", line 639, in __connect
    connection = pool._invoke_creator(self)
  File "/Users/eiji/anaconda3/lib/python3.7/site-packages/sqlalchemy/engine/strategies.py", line 114, in connect
    return dialect.connect(*cargs, **cparams)
  File "/Users/eiji/anaconda3/lib/python3.7/site-packages/sqlalchemy/engine/default.py", line 482, in connect
    return self.dbapi.connect(*cargs, **cparams)
  File "/Users/eiji/anaconda3/lib/python3.7/site-packages/psycopg2/__init__.py", line 126, in connect
    conn = _connect(dsn, connection_factory=connection_factory, **kwasync)
psycopg2.OperationalError: FATAL:  role "amy" does not exist


The above exception was the direct cause of the following exception:

Traceback (most recent call last):
  File "/Users/eiji/anaconda3/lib/python3.7/site-packages/flask/app.py", line 2311, in wsgi_app
    response = self.full_dispatch_request()
  File "/Users/eiji/anaconda3/lib/python3.7/site-packages/flask/app.py", line 1834, in full_dispatch_request
    rv = self.handle_user_exception(e)
  File "/Users/eiji/anaconda3/lib/python3.7/site-packages/flask/app.py", line 1737, in handle_user_exception
    reraise(exc_type, exc_value, tb)
  File "/Users/eiji/anaconda3/lib/python3.7/site-packages/flask/_compat.py", line 36, in reraise
    raise value
  File "/Users/eiji/anaconda3/lib/python3.7/site-packages/flask/app.py", line 1832, in full_dispatch_request
    rv = self.dispatch_request()
  File "/Users/eiji/anaconda3/lib/python3.7/site-packages/flask/app.py", line 1818, in dispatch_request
    return self.view_functions[rule.endpoint](**req.view_args)
  File "/Users/eiji/Desktop/class-demo/01_fyyur/projects/app.py", line 137, in venues
    areas=Venue.query.all()
  File "/Users/eiji/anaconda3/lib/python3.7/site-packages/sqlalchemy/orm/query.py", line 3211, in all
    return list(self)
  File "/Users/eiji/anaconda3/lib/python3.7/site-packages/sqlalchemy/orm/query.py", line 3367, in __iter__
    return self._execute_and_instances(context)
  File "/Users/eiji/anaconda3/lib/python3.7/site-packages/sqlalchemy/orm/query.py", line 3389, in _execute_and_instances
    querycontext, self._connection_from_session, close_with_result=True
  File "/Users/eiji/anaconda3/lib/python3.7/site-packages/sqlalchemy/orm/query.py", line 3404, in _get_bind_args
    mapper=self._bind_mapper(), clause=querycontext.statement, **kw
  File "/Users/eiji/anaconda3/lib/python3.7/site-packages/sqlalchemy/orm/query.py", line 3382, in _connection_from_session
    conn = self.session.connection(**kw)
  File "/Users/eiji/anaconda3/lib/python3.7/site-packages/sqlalchemy/orm/session.py", line 1124, in connection
    execution_options=execution_options,
  File "/Users/eiji/anaconda3/lib/python3.7/site-packages/sqlalchemy/orm/session.py", line 1130, in _connection_for_bind
    engine, execution_options
  File "/Users/eiji/anaconda3/lib/python3.7/site-packages/sqlalchemy/orm/session.py", line 431, in _connection_for_bind
    conn = bind._contextual_connect()
  File "/Users/eiji/anaconda3/lib/python3.7/site-packages/sqlalchemy/engine/base.py", line 2242, in _contextual_connect
    self._wrap_pool_connect(self.pool.connect, None),
  File "/Users/eiji/anaconda3/lib/python3.7/site-packages/sqlalchemy/engine/base.py", line 2280, in _wrap_pool_connect
    e, dialect, self
  File "/Users/eiji/anaconda3/lib/python3.7/site-packages/sqlalchemy/engine/base.py", line 1547, in _handle_dbapi_exception_noconnection
    util.raise_from_cause(sqlalchemy_exception, exc_info)
  File "/Users/eiji/anaconda3/lib/python3.7/site-packages/sqlalchemy/util/compat.py", line 398, in raise_from_cause
    reraise(type(exception), exception, tb=exc_tb, cause=cause)
  File "/Users/eiji/anaconda3/lib/python3.7/site-packages/sqlalchemy/util/compat.py", line 152, in reraise
    raise value.with_traceback(tb)
  File "/Users/eiji/anaconda3/lib/python3.7/site-packages/sqlalchemy/engine/base.py", line 2276, in _wrap_pool_connect
    return fn()
  File "/Users/eiji/anaconda3/lib/python3.7/site-packages/sqlalchemy/pool/base.py", line 363, in connect
    return _ConnectionFairy._checkout(self)
  File "/Users/eiji/anaconda3/lib/python3.7/site-packages/sqlalchemy/pool/base.py", line 760, in _checkout
    fairy = _ConnectionRecord.checkout(pool)
  File "/Users/eiji/anaconda3/lib/python3.7/site-packages/sqlalchemy/pool/base.py", line 492, in checkout
    rec = pool._do_get()
  File "/Users/eiji/anaconda3/lib/python3.7/site-packages/sqlalchemy/pool/impl.py", line 139, in _do_get
    self._dec_overflow()
  File "/Users/eiji/anaconda3/lib/python3.7/site-packages/sqlalchemy/util/langhelpers.py", line 68, in __exit__
    compat.reraise(exc_type, exc_value, exc_tb)
  File "/Users/eiji/anaconda3/lib/python3.7/site-packages/sqlalchemy/util/compat.py", line 153, in reraise
    raise value
  File "/Users/eiji/anaconda3/lib/python3.7/site-packages/sqlalchemy/pool/impl.py", line 136, in _do_get
    return self._create_connection()
  File "/Users/eiji/anaconda3/lib/python3.7/site-packages/sqlalchemy/pool/base.py", line 308, in _create_connection
    return _ConnectionRecord(self)
  File "/Users/eiji/anaconda3/lib/python3.7/site-packages/sqlalchemy/pool/base.py", line 437, in __init__
    self.__connect(first_connect_check=True)
  File "/Users/eiji/anaconda3/lib/python3.7/site-packages/sqlalchemy/pool/base.py", line 639, in __connect
    connection = pool._invoke_creator(self)
  File "/Users/eiji/anaconda3/lib/python3.7/site-packages/sqlalchemy/engine/strategies.py", line 114, in connect
    return dialect.connect(*cargs, **cparams)
  File "/Users/eiji/anaconda3/lib/python3.7/site-packages/sqlalchemy/engine/default.py", line 482, in connect
    return self.dbapi.connect(*cargs, **cparams)
  File "/Users/eiji/anaconda3/lib/python3.7/site-packages/psycopg2/__init__.py", line 126, in connect
    conn = _connect(dsn, connection_factory=connection_factory, **kwasync)
sqlalchemy.exc.OperationalError: (psycopg2.OperationalError) FATAL:  role "amy" does not exist

(Background on this error at: http://sqlalche.me/e/e3q8)
2020-01-05 17:13:06,801 ERROR: Exception on /venues [GET] [in /Users/eiji/anaconda3/lib/python3.7/site-packages/flask/app.py:1780]
Traceback (most recent call last):
  File "/Users/eiji/anaconda3/lib/python3.7/site-packages/sqlalchemy/engine/base.py", line 2276, in _wrap_pool_connect
    return fn()
  File "/Users/eiji/anaconda3/lib/python3.7/site-packages/sqlalchemy/pool/base.py", line 363, in connect
    return _ConnectionFairy._checkout(self)
  File "/Users/eiji/anaconda3/lib/python3.7/site-packages/sqlalchemy/pool/base.py", line 760, in _checkout
    fairy = _ConnectionRecord.checkout(pool)
  File "/Users/eiji/anaconda3/lib/python3.7/site-packages/sqlalchemy/pool/base.py", line 492, in checkout
    rec = pool._do_get()
  File "/Users/eiji/anaconda3/lib/python3.7/site-packages/sqlalchemy/pool/impl.py", line 139, in _do_get
    self._dec_overflow()
  File "/Users/eiji/anaconda3/lib/python3.7/site-packages/sqlalchemy/util/langhelpers.py", line 68, in __exit__
    compat.reraise(exc_type, exc_value, exc_tb)
  File "/Users/eiji/anaconda3/lib/python3.7/site-packages/sqlalchemy/util/compat.py", line 153, in reraise
    raise value
  File "/Users/eiji/anaconda3/lib/python3.7/site-packages/sqlalchemy/pool/impl.py", line 136, in _do_get
    return self._create_connection()
  File "/Users/eiji/anaconda3/lib/python3.7/site-packages/sqlalchemy/pool/base.py", line 308, in _create_connection
    return _ConnectionRecord(self)
  File "/Users/eiji/anaconda3/lib/python3.7/site-packages/sqlalchemy/pool/base.py", line 437, in __init__
    self.__connect(first_connect_check=True)
  File "/Users/eiji/anaconda3/lib/python3.7/site-packages/sqlalchemy/pool/base.py", line 639, in __connect
    connection = pool._invoke_creator(self)
  File "/Users/eiji/anaconda3/lib/python3.7/site-packages/sqlalchemy/engine/strategies.py", line 114, in connect
    return dialect.connect(*cargs, **cparams)
  File "/Users/eiji/anaconda3/lib/python3.7/site-packages/sqlalchemy/engine/default.py", line 482, in connect
    return self.dbapi.connect(*cargs, **cparams)
  File "/Users/eiji/anaconda3/lib/python3.7/site-packages/psycopg2/__init__.py", line 126, in connect
    conn = _connect(dsn, connection_factory=connection_factory, **kwasync)
psycopg2.OperationalError: FATAL:  role "amy" does not exist


The above exception was the direct cause of the following exception:

Traceback (most recent call last):
  File "/Users/eiji/anaconda3/lib/python3.7/site-packages/flask/app.py", line 2311, in wsgi_app
    response = self.full_dispatch_request()
  File "/Users/eiji/anaconda3/lib/python3.7/site-packages/flask/app.py", line 1834, in full_dispatch_request
    rv = self.handle_user_exception(e)
  File "/Users/eiji/anaconda3/lib/python3.7/site-packages/flask/app.py", line 1737, in handle_user_exception
    reraise(exc_type, exc_value, tb)
  File "/Users/eiji/anaconda3/lib/python3.7/site-packages/flask/_compat.py", line 36, in reraise
    raise value
  File "/Users/eiji/anaconda3/lib/python3.7/site-packages/flask/app.py", line 1832, in full_dispatch_request
    rv = self.dispatch_request()
  File "/Users/eiji/anaconda3/lib/python3.7/site-packages/flask/app.py", line 1818, in dispatch_request
    return self.view_functions[rule.endpoint](**req.view_args)
  File "/Users/eiji/Desktop/class-demo/01_fyyur/projects/app.py", line 137, in venues
    areas=Venue.query.all()
  File "/Users/eiji/anaconda3/lib/python3.7/site-packages/sqlalchemy/orm/query.py", line 3211, in all
    return list(self)
  File "/Users/eiji/anaconda3/lib/python3.7/site-packages/sqlalchemy/orm/query.py", line 3367, in __iter__
    return self._execute_and_instances(context)
  File "/Users/eiji/anaconda3/lib/python3.7/site-packages/sqlalchemy/orm/query.py", line 3389, in _execute_and_instances
    querycontext, self._connection_from_session, close_with_result=True
  File "/Users/eiji/anaconda3/lib/python3.7/site-packages/sqlalchemy/orm/query.py", line 3404, in _get_bind_args
    mapper=self._bind_mapper(), clause=querycontext.statement, **kw
  File "/Users/eiji/anaconda3/lib/python3.7/site-packages/sqlalchemy/orm/query.py", line 3382, in _connection_from_session
    conn = self.session.connection(**kw)
  File "/Users/eiji/anaconda3/lib/python3.7/site-packages/sqlalchemy/orm/session.py", line 1124, in connection
    execution_options=execution_options,
  File "/Users/eiji/anaconda3/lib/python3.7/site-packages/sqlalchemy/orm/session.py", line 1130, in _connection_for_bind
    engine, execution_options
  File "/Users/eiji/anaconda3/lib/python3.7/site-packages/sqlalchemy/orm/session.py", line 431, in _connection_for_bind
    conn = bind._contextual_connect()
  File "/Users/eiji/anaconda3/lib/python3.7/site-packages/sqlalchemy/engine/base.py", line 2242, in _contextual_connect
    self._wrap_pool_connect(self.pool.connect, None),
  File "/Users/eiji/anaconda3/lib/python3.7/site-packages/sqlalchemy/engine/base.py", line 2280, in _wrap_pool_connect
    e, dialect, self
  File "/Users/eiji/anaconda3/lib/python3.7/site-packages/sqlalchemy/engine/base.py", line 1547, in _handle_dbapi_exception_noconnection
    util.raise_from_cause(sqlalchemy_exception, exc_info)
  File "/Users/eiji/anaconda3/lib/python3.7/site-packages/sqlalchemy/util/compat.py", line 398, in raise_from_cause
    reraise(type(exception), exception, tb=exc_tb, cause=cause)
  File "/Users/eiji/anaconda3/lib/python3.7/site-packages/sqlalchemy/util/compat.py", line 152, in reraise
    raise value.with_traceback(tb)
  File "/Users/eiji/anaconda3/lib/python3.7/site-packages/sqlalchemy/engine/base.py", line 2276, in _wrap_pool_connect
    return fn()
  File "/Users/eiji/anaconda3/lib/python3.7/site-packages/sqlalchemy/pool/base.py", line 363, in connect
    return _ConnectionFairy._checkout(self)
  File "/Users/eiji/anaconda3/lib/python3.7/site-packages/sqlalchemy/pool/base.py", line 760, in _checkout
    fairy = _ConnectionRecord.checkout(pool)
  File "/Users/eiji/anaconda3/lib/python3.7/site-packages/sqlalchemy/pool/base.py", line 492, in checkout
    rec = pool._do_get()
  File "/Users/eiji/anaconda3/lib/python3.7/site-packages/sqlalchemy/pool/impl.py", line 139, in _do_get
    self._dec_overflow()
  File "/Users/eiji/anaconda3/lib/python3.7/site-packages/sqlalchemy/util/langhelpers.py", line 68, in __exit__
    compat.reraise(exc_type, exc_value, exc_tb)
  File "/Users/eiji/anaconda3/lib/python3.7/site-packages/sqlalchemy/util/compat.py", line 153, in reraise
    raise value
  File "/Users/eiji/anaconda3/lib/python3.7/site-packages/sqlalchemy/pool/impl.py", line 136, in _do_get
    return self._create_connection()
  File "/Users/eiji/anaconda3/lib/python3.7/site-packages/sqlalchemy/pool/base.py", line 308, in _create_connection
    return _ConnectionRecord(self)
  File "/Users/eiji/anaconda3/lib/python3.7/site-packages/sqlalchemy/pool/base.py", line 437, in __init__
    self.__connect(first_connect_check=True)
  File "/Users/eiji/anaconda3/lib/python3.7/site-packages/sqlalchemy/pool/base.py", line 639, in __connect
    connection = pool._invoke_creator(self)
  File "/Users/eiji/anaconda3/lib/python3.7/site-packages/sqlalchemy/engine/strategies.py", line 114, in connect
    return dialect.connect(*cargs, **cparams)
  File "/Users/eiji/anaconda3/lib/python3.7/site-packages/sqlalchemy/engine/default.py", line 482, in connect
    return self.dbapi.connect(*cargs, **cparams)
  File "/Users/eiji/anaconda3/lib/python3.7/site-packages/psycopg2/__init__.py", line 126, in connect
    conn = _connect(dsn, connection_factory=connection_factory, **kwasync)
sqlalchemy.exc.OperationalError: (psycopg2.OperationalError) FATAL:  role "amy" does not exist

(Background on this error at: http://sqlalche.me/e/e3q8)
2020-01-05 17:13:13,873 ERROR: Exception on /venues [GET] [in /Users/eiji/anaconda3/lib/python3.7/site-packages/flask/app.py:1780]
Traceback (most recent call last):
  File "/Users/eiji/anaconda3/lib/python3.7/site-packages/sqlalchemy/engine/base.py", line 2276, in _wrap_pool_connect
    return fn()
  File "/Users/eiji/anaconda3/lib/python3.7/site-packages/sqlalchemy/pool/base.py", line 363, in connect
    return _ConnectionFairy._checkout(self)
  File "/Users/eiji/anaconda3/lib/python3.7/site-packages/sqlalchemy/pool/base.py", line 760, in _checkout
    fairy = _ConnectionRecord.checkout(pool)
  File "/Users/eiji/anaconda3/lib/python3.7/site-packages/sqlalchemy/pool/base.py", line 492, in checkout
    rec = pool._do_get()
  File "/Users/eiji/anaconda3/lib/python3.7/site-packages/sqlalchemy/pool/impl.py", line 139, in _do_get
    self._dec_overflow()
  File "/Users/eiji/anaconda3/lib/python3.7/site-packages/sqlalchemy/util/langhelpers.py", line 68, in __exit__
    compat.reraise(exc_type, exc_value, exc_tb)
  File "/Users/eiji/anaconda3/lib/python3.7/site-packages/sqlalchemy/util/compat.py", line 153, in reraise
    raise value
  File "/Users/eiji/anaconda3/lib/python3.7/site-packages/sqlalchemy/pool/impl.py", line 136, in _do_get
    return self._create_connection()
  File "/Users/eiji/anaconda3/lib/python3.7/site-packages/sqlalchemy/pool/base.py", line 308, in _create_connection
    return _ConnectionRecord(self)
  File "/Users/eiji/anaconda3/lib/python3.7/site-packages/sqlalchemy/pool/base.py", line 437, in __init__
    self.__connect(first_connect_check=True)
  File "/Users/eiji/anaconda3/lib/python3.7/site-packages/sqlalchemy/pool/base.py", line 639, in __connect
    connection = pool._invoke_creator(self)
  File "/Users/eiji/anaconda3/lib/python3.7/site-packages/sqlalchemy/engine/strategies.py", line 114, in connect
    return dialect.connect(*cargs, **cparams)
  File "/Users/eiji/anaconda3/lib/python3.7/site-packages/sqlalchemy/engine/default.py", line 482, in connect
    return self.dbapi.connect(*cargs, **cparams)
  File "/Users/eiji/anaconda3/lib/python3.7/site-packages/psycopg2/__init__.py", line 126, in connect
    conn = _connect(dsn, connection_factory=connection_factory, **kwasync)
psycopg2.OperationalError: FATAL:  role "amy" does not exist


The above exception was the direct cause of the following exception:

Traceback (most recent call last):
  File "/Users/eiji/anaconda3/lib/python3.7/site-packages/flask/app.py", line 2311, in wsgi_app
    response = self.full_dispatch_request()
  File "/Users/eiji/anaconda3/lib/python3.7/site-packages/flask/app.py", line 1834, in full_dispatch_request
    rv = self.handle_user_exception(e)
  File "/Users/eiji/anaconda3/lib/python3.7/site-packages/flask/app.py", line 1737, in handle_user_exception
    reraise(exc_type, exc_value, tb)
  File "/Users/eiji/anaconda3/lib/python3.7/site-packages/flask/_compat.py", line 36, in reraise
    raise value
  File "/Users/eiji/anaconda3/lib/python3.7/site-packages/flask/app.py", line 1832, in full_dispatch_request
    rv = self.dispatch_request()
  File "/Users/eiji/anaconda3/lib/python3.7/site-packages/flask/app.py", line 1818, in dispatch_request
    return self.view_functions[rule.endpoint](**req.view_args)
  File "/Users/eiji/Desktop/class-demo/01_fyyur/projects/app.py", line 137, in venues
    )
  File "/Users/eiji/anaconda3/lib/python3.7/site-packages/sqlalchemy/orm/query.py", line 3211, in all
    return list(self)
  File "/Users/eiji/anaconda3/lib/python3.7/site-packages/sqlalchemy/orm/query.py", line 3367, in __iter__
    return self._execute_and_instances(context)
  File "/Users/eiji/anaconda3/lib/python3.7/site-packages/sqlalchemy/orm/query.py", line 3389, in _execute_and_instances
    querycontext, self._connection_from_session, close_with_result=True
  File "/Users/eiji/anaconda3/lib/python3.7/site-packages/sqlalchemy/orm/query.py", line 3404, in _get_bind_args
    mapper=self._bind_mapper(), clause=querycontext.statement, **kw
  File "/Users/eiji/anaconda3/lib/python3.7/site-packages/sqlalchemy/orm/query.py", line 3382, in _connection_from_session
    conn = self.session.connection(**kw)
  File "/Users/eiji/anaconda3/lib/python3.7/site-packages/sqlalchemy/orm/session.py", line 1124, in connection
    execution_options=execution_options,
  File "/Users/eiji/anaconda3/lib/python3.7/site-packages/sqlalchemy/orm/session.py", line 1130, in _connection_for_bind
    engine, execution_options
  File "/Users/eiji/anaconda3/lib/python3.7/site-packages/sqlalchemy/orm/session.py", line 431, in _connection_for_bind
    conn = bind._contextual_connect()
  File "/Users/eiji/anaconda3/lib/python3.7/site-packages/sqlalchemy/engine/base.py", line 2242, in _contextual_connect
    self._wrap_pool_connect(self.pool.connect, None),
  File "/Users/eiji/anaconda3/lib/python3.7/site-packages/sqlalchemy/engine/base.py", line 2280, in _wrap_pool_connect
    e, dialect, self
  File "/Users/eiji/anaconda3/lib/python3.7/site-packages/sqlalchemy/engine/base.py", line 1547, in _handle_dbapi_exception_noconnection
    util.raise_from_cause(sqlalchemy_exception, exc_info)
  File "/Users/eiji/anaconda3/lib/python3.7/site-packages/sqlalchemy/util/compat.py", line 398, in raise_from_cause
    reraise(type(exception), exception, tb=exc_tb, cause=cause)
  File "/Users/eiji/anaconda3/lib/python3.7/site-packages/sqlalchemy/util/compat.py", line 152, in reraise
    raise value.with_traceback(tb)
  File "/Users/eiji/anaconda3/lib/python3.7/site-packages/sqlalchemy/engine/base.py", line 2276, in _wrap_pool_connect
    return fn()
  File "/Users/eiji/anaconda3/lib/python3.7/site-packages/sqlalchemy/pool/base.py", line 363, in connect
    return _ConnectionFairy._checkout(self)
  File "/Users/eiji/anaconda3/lib/python3.7/site-packages/sqlalchemy/pool/base.py", line 760, in _checkout
    fairy = _ConnectionRecord.checkout(pool)
  File "/Users/eiji/anaconda3/lib/python3.7/site-packages/sqlalchemy/pool/base.py", line 492, in checkout
    rec = pool._do_get()
  File "/Users/eiji/anaconda3/lib/python3.7/site-packages/sqlalchemy/pool/impl.py", line 139, in _do_get
    self._dec_overflow()
  File "/Users/eiji/anaconda3/lib/python3.7/site-packages/sqlalchemy/util/langhelpers.py", line 68, in __exit__
    compat.reraise(exc_type, exc_value, exc_tb)
  File "/Users/eiji/anaconda3/lib/python3.7/site-packages/sqlalchemy/util/compat.py", line 153, in reraise
    raise value
  File "/Users/eiji/anaconda3/lib/python3.7/site-packages/sqlalchemy/pool/impl.py", line 136, in _do_get
    return self._create_connection()
  File "/Users/eiji/anaconda3/lib/python3.7/site-packages/sqlalchemy/pool/base.py", line 308, in _create_connection
    return _ConnectionRecord(self)
  File "/Users/eiji/anaconda3/lib/python3.7/site-packages/sqlalchemy/pool/base.py", line 437, in __init__
    self.__connect(first_connect_check=True)
  File "/Users/eiji/anaconda3/lib/python3.7/site-packages/sqlalchemy/pool/base.py", line 639, in __connect
    connection = pool._invoke_creator(self)
  File "/Users/eiji/anaconda3/lib/python3.7/site-packages/sqlalchemy/engine/strategies.py", line 114, in connect
    return dialect.connect(*cargs, **cparams)
  File "/Users/eiji/anaconda3/lib/python3.7/site-packages/sqlalchemy/engine/default.py", line 482, in connect
    return self.dbapi.connect(*cargs, **cparams)
  File "/Users/eiji/anaconda3/lib/python3.7/site-packages/psycopg2/__init__.py", line 126, in connect
    conn = _connect(dsn, connection_factory=connection_factory, **kwasync)
sqlalchemy.exc.OperationalError: (psycopg2.OperationalError) FATAL:  role "amy" does not exist

(Background on this error at: http://sqlalche.me/e/e3q8)
2020-01-05 17:13:15,598 ERROR: Exception on /venues [GET] [in /Users/eiji/anaconda3/lib/python3.7/site-packages/flask/app.py:1780]
Traceback (most recent call last):
  File "/Users/eiji/anaconda3/lib/python3.7/site-packages/sqlalchemy/engine/base.py", line 2276, in _wrap_pool_connect
    return fn()
  File "/Users/eiji/anaconda3/lib/python3.7/site-packages/sqlalchemy/pool/base.py", line 363, in connect
    return _ConnectionFairy._checkout(self)
  File "/Users/eiji/anaconda3/lib/python3.7/site-packages/sqlalchemy/pool/base.py", line 760, in _checkout
    fairy = _ConnectionRecord.checkout(pool)
  File "/Users/eiji/anaconda3/lib/python3.7/site-packages/sqlalchemy/pool/base.py", line 492, in checkout
    rec = pool._do_get()
  File "/Users/eiji/anaconda3/lib/python3.7/site-packages/sqlalchemy/pool/impl.py", line 139, in _do_get
    self._dec_overflow()
  File "/Users/eiji/anaconda3/lib/python3.7/site-packages/sqlalchemy/util/langhelpers.py", line 68, in __exit__
    compat.reraise(exc_type, exc_value, exc_tb)
  File "/Users/eiji/anaconda3/lib/python3.7/site-packages/sqlalchemy/util/compat.py", line 153, in reraise
    raise value
  File "/Users/eiji/anaconda3/lib/python3.7/site-packages/sqlalchemy/pool/impl.py", line 136, in _do_get
    return self._create_connection()
  File "/Users/eiji/anaconda3/lib/python3.7/site-packages/sqlalchemy/pool/base.py", line 308, in _create_connection
    return _ConnectionRecord(self)
  File "/Users/eiji/anaconda3/lib/python3.7/site-packages/sqlalchemy/pool/base.py", line 437, in __init__
    self.__connect(first_connect_check=True)
  File "/Users/eiji/anaconda3/lib/python3.7/site-packages/sqlalchemy/pool/base.py", line 639, in __connect
    connection = pool._invoke_creator(self)
  File "/Users/eiji/anaconda3/lib/python3.7/site-packages/sqlalchemy/engine/strategies.py", line 114, in connect
    return dialect.connect(*cargs, **cparams)
  File "/Users/eiji/anaconda3/lib/python3.7/site-packages/sqlalchemy/engine/default.py", line 482, in connect
    return self.dbapi.connect(*cargs, **cparams)
  File "/Users/eiji/anaconda3/lib/python3.7/site-packages/psycopg2/__init__.py", line 126, in connect
    conn = _connect(dsn, connection_factory=connection_factory, **kwasync)
psycopg2.OperationalError: FATAL:  role "amy" does not exist


The above exception was the direct cause of the following exception:

Traceback (most recent call last):
  File "/Users/eiji/anaconda3/lib/python3.7/site-packages/flask/app.py", line 2311, in wsgi_app
    response = self.full_dispatch_request()
  File "/Users/eiji/anaconda3/lib/python3.7/site-packages/flask/app.py", line 1834, in full_dispatch_request
    rv = self.handle_user_exception(e)
  File "/Users/eiji/anaconda3/lib/python3.7/site-packages/flask/app.py", line 1737, in handle_user_exception
    reraise(exc_type, exc_value, tb)
  File "/Users/eiji/anaconda3/lib/python3.7/site-packages/flask/_compat.py", line 36, in reraise
    raise value
  File "/Users/eiji/anaconda3/lib/python3.7/site-packages/flask/app.py", line 1832, in full_dispatch_request
    rv = self.dispatch_request()
  File "/Users/eiji/anaconda3/lib/python3.7/site-packages/flask/app.py", line 1818, in dispatch_request
    return self.view_functions[rule.endpoint](**req.view_args)
  File "/Users/eiji/Desktop/class-demo/01_fyyur/projects/app.py", line 137, in venues
    )
  File "/Users/eiji/anaconda3/lib/python3.7/site-packages/sqlalchemy/orm/query.py", line 3211, in all
    return list(self)
  File "/Users/eiji/anaconda3/lib/python3.7/site-packages/sqlalchemy/orm/query.py", line 3367, in __iter__
    return self._execute_and_instances(context)
  File "/Users/eiji/anaconda3/lib/python3.7/site-packages/sqlalchemy/orm/query.py", line 3389, in _execute_and_instances
    querycontext, self._connection_from_session, close_with_result=True
  File "/Users/eiji/anaconda3/lib/python3.7/site-packages/sqlalchemy/orm/query.py", line 3404, in _get_bind_args
    mapper=self._bind_mapper(), clause=querycontext.statement, **kw
  File "/Users/eiji/anaconda3/lib/python3.7/site-packages/sqlalchemy/orm/query.py", line 3382, in _connection_from_session
    conn = self.session.connection(**kw)
  File "/Users/eiji/anaconda3/lib/python3.7/site-packages/sqlalchemy/orm/session.py", line 1124, in connection
    execution_options=execution_options,
  File "/Users/eiji/anaconda3/lib/python3.7/site-packages/sqlalchemy/orm/session.py", line 1130, in _connection_for_bind
    engine, execution_options
  File "/Users/eiji/anaconda3/lib/python3.7/site-packages/sqlalchemy/orm/session.py", line 431, in _connection_for_bind
    conn = bind._contextual_connect()
  File "/Users/eiji/anaconda3/lib/python3.7/site-packages/sqlalchemy/engine/base.py", line 2242, in _contextual_connect
    self._wrap_pool_connect(self.pool.connect, None),
  File "/Users/eiji/anaconda3/lib/python3.7/site-packages/sqlalchemy/engine/base.py", line 2280, in _wrap_pool_connect
    e, dialect, self
  File "/Users/eiji/anaconda3/lib/python3.7/site-packages/sqlalchemy/engine/base.py", line 1547, in _handle_dbapi_exception_noconnection
    util.raise_from_cause(sqlalchemy_exception, exc_info)
  File "/Users/eiji/anaconda3/lib/python3.7/site-packages/sqlalchemy/util/compat.py", line 398, in raise_from_cause
    reraise(type(exception), exception, tb=exc_tb, cause=cause)
  File "/Users/eiji/anaconda3/lib/python3.7/site-packages/sqlalchemy/util/compat.py", line 152, in reraise
    raise value.with_traceback(tb)
  File "/Users/eiji/anaconda3/lib/python3.7/site-packages/sqlalchemy/engine/base.py", line 2276, in _wrap_pool_connect
    return fn()
  File "/Users/eiji/anaconda3/lib/python3.7/site-packages/sqlalchemy/pool/base.py", line 363, in connect
    return _ConnectionFairy._checkout(self)
  File "/Users/eiji/anaconda3/lib/python3.7/site-packages/sqlalchemy/pool/base.py", line 760, in _checkout
    fairy = _ConnectionRecord.checkout(pool)
  File "/Users/eiji/anaconda3/lib/python3.7/site-packages/sqlalchemy/pool/base.py", line 492, in checkout
    rec = pool._do_get()
  File "/Users/eiji/anaconda3/lib/python3.7/site-packages/sqlalchemy/pool/impl.py", line 139, in _do_get
    self._dec_overflow()
  File "/Users/eiji/anaconda3/lib/python3.7/site-packages/sqlalchemy/util/langhelpers.py", line 68, in __exit__
    compat.reraise(exc_type, exc_value, exc_tb)
  File "/Users/eiji/anaconda3/lib/python3.7/site-packages/sqlalchemy/util/compat.py", line 153, in reraise
    raise value
  File "/Users/eiji/anaconda3/lib/python3.7/site-packages/sqlalchemy/pool/impl.py", line 136, in _do_get
    return self._create_connection()
  File "/Users/eiji/anaconda3/lib/python3.7/site-packages/sqlalchemy/pool/base.py", line 308, in _create_connection
    return _ConnectionRecord(self)
  File "/Users/eiji/anaconda3/lib/python3.7/site-packages/sqlalchemy/pool/base.py", line 437, in __init__
    self.__connect(first_connect_check=True)
  File "/Users/eiji/anaconda3/lib/python3.7/site-packages/sqlalchemy/pool/base.py", line 639, in __connect
    connection = pool._invoke_creator(self)
  File "/Users/eiji/anaconda3/lib/python3.7/site-packages/sqlalchemy/engine/strategies.py", line 114, in connect
    return dialect.connect(*cargs, **cparams)
  File "/Users/eiji/anaconda3/lib/python3.7/site-packages/sqlalchemy/engine/default.py", line 482, in connect
    return self.dbapi.connect(*cargs, **cparams)
  File "/Users/eiji/anaconda3/lib/python3.7/site-packages/psycopg2/__init__.py", line 126, in connect
    conn = _connect(dsn, connection_factory=connection_factory, **kwasync)
sqlalchemy.exc.OperationalError: (psycopg2.OperationalError) FATAL:  role "amy" does not exist

(Background on this error at: http://sqlalche.me/e/e3q8)
2020-01-05 17:13:17,909 ERROR: Exception on /venues [GET] [in /Users/eiji/anaconda3/lib/python3.7/site-packages/flask/app.py:1780]
Traceback (most recent call last):
  File "/Users/eiji/anaconda3/lib/python3.7/site-packages/sqlalchemy/engine/base.py", line 2276, in _wrap_pool_connect
    return fn()
  File "/Users/eiji/anaconda3/lib/python3.7/site-packages/sqlalchemy/pool/base.py", line 363, in connect
    return _ConnectionFairy._checkout(self)
  File "/Users/eiji/anaconda3/lib/python3.7/site-packages/sqlalchemy/pool/base.py", line 760, in _checkout
    fairy = _ConnectionRecord.checkout(pool)
  File "/Users/eiji/anaconda3/lib/python3.7/site-packages/sqlalchemy/pool/base.py", line 492, in checkout
    rec = pool._do_get()
  File "/Users/eiji/anaconda3/lib/python3.7/site-packages/sqlalchemy/pool/impl.py", line 139, in _do_get
    self._dec_overflow()
  File "/Users/eiji/anaconda3/lib/python3.7/site-packages/sqlalchemy/util/langhelpers.py", line 68, in __exit__
    compat.reraise(exc_type, exc_value, exc_tb)
  File "/Users/eiji/anaconda3/lib/python3.7/site-packages/sqlalchemy/util/compat.py", line 153, in reraise
    raise value
  File "/Users/eiji/anaconda3/lib/python3.7/site-packages/sqlalchemy/pool/impl.py", line 136, in _do_get
    return self._create_connection()
  File "/Users/eiji/anaconda3/lib/python3.7/site-packages/sqlalchemy/pool/base.py", line 308, in _create_connection
    return _ConnectionRecord(self)
  File "/Users/eiji/anaconda3/lib/python3.7/site-packages/sqlalchemy/pool/base.py", line 437, in __init__
    self.__connect(first_connect_check=True)
  File "/Users/eiji/anaconda3/lib/python3.7/site-packages/sqlalchemy/pool/base.py", line 639, in __connect
    connection = pool._invoke_creator(self)
  File "/Users/eiji/anaconda3/lib/python3.7/site-packages/sqlalchemy/engine/strategies.py", line 114, in connect
    return dialect.connect(*cargs, **cparams)
  File "/Users/eiji/anaconda3/lib/python3.7/site-packages/sqlalchemy/engine/default.py", line 482, in connect
    return self.dbapi.connect(*cargs, **cparams)
  File "/Users/eiji/anaconda3/lib/python3.7/site-packages/psycopg2/__init__.py", line 126, in connect
    conn = _connect(dsn, connection_factory=connection_factory, **kwasync)
psycopg2.OperationalError: FATAL:  role "amy" does not exist


The above exception was the direct cause of the following exception:

Traceback (most recent call last):
  File "/Users/eiji/anaconda3/lib/python3.7/site-packages/flask/app.py", line 2311, in wsgi_app
    response = self.full_dispatch_request()
  File "/Users/eiji/anaconda3/lib/python3.7/site-packages/flask/app.py", line 1834, in full_dispatch_request
    rv = self.handle_user_exception(e)
  File "/Users/eiji/anaconda3/lib/python3.7/site-packages/flask/app.py", line 1737, in handle_user_exception
    reraise(exc_type, exc_value, tb)
  File "/Users/eiji/anaconda3/lib/python3.7/site-packages/flask/_compat.py", line 36, in reraise
    raise value
  File "/Users/eiji/anaconda3/lib/python3.7/site-packages/flask/app.py", line 1832, in full_dispatch_request
    rv = self.dispatch_request()
  File "/Users/eiji/anaconda3/lib/python3.7/site-packages/flask/app.py", line 1818, in dispatch_request
    return self.view_functions[rule.endpoint](**req.view_args)
  File "/Users/eiji/Desktop/class-demo/01_fyyur/projects/app.py", line 137, in venues
    )
  File "/Users/eiji/anaconda3/lib/python3.7/site-packages/sqlalchemy/orm/query.py", line 3211, in all
    return list(self)
  File "/Users/eiji/anaconda3/lib/python3.7/site-packages/sqlalchemy/orm/query.py", line 3367, in __iter__
    return self._execute_and_instances(context)
  File "/Users/eiji/anaconda3/lib/python3.7/site-packages/sqlalchemy/orm/query.py", line 3389, in _execute_and_instances
    querycontext, self._connection_from_session, close_with_result=True
  File "/Users/eiji/anaconda3/lib/python3.7/site-packages/sqlalchemy/orm/query.py", line 3404, in _get_bind_args
    mapper=self._bind_mapper(), clause=querycontext.statement, **kw
  File "/Users/eiji/anaconda3/lib/python3.7/site-packages/sqlalchemy/orm/query.py", line 3382, in _connection_from_session
    conn = self.session.connection(**kw)
  File "/Users/eiji/anaconda3/lib/python3.7/site-packages/sqlalchemy/orm/session.py", line 1124, in connection
    execution_options=execution_options,
  File "/Users/eiji/anaconda3/lib/python3.7/site-packages/sqlalchemy/orm/session.py", line 1130, in _connection_for_bind
    engine, execution_options
  File "/Users/eiji/anaconda3/lib/python3.7/site-packages/sqlalchemy/orm/session.py", line 431, in _connection_for_bind
    conn = bind._contextual_connect()
  File "/Users/eiji/anaconda3/lib/python3.7/site-packages/sqlalchemy/engine/base.py", line 2242, in _contextual_connect
    self._wrap_pool_connect(self.pool.connect, None),
  File "/Users/eiji/anaconda3/lib/python3.7/site-packages/sqlalchemy/engine/base.py", line 2280, in _wrap_pool_connect
    e, dialect, self
  File "/Users/eiji/anaconda3/lib/python3.7/site-packages/sqlalchemy/engine/base.py", line 1547, in _handle_dbapi_exception_noconnection
    util.raise_from_cause(sqlalchemy_exception, exc_info)
  File "/Users/eiji/anaconda3/lib/python3.7/site-packages/sqlalchemy/util/compat.py", line 398, in raise_from_cause
    reraise(type(exception), exception, tb=exc_tb, cause=cause)
  File "/Users/eiji/anaconda3/lib/python3.7/site-packages/sqlalchemy/util/compat.py", line 152, in reraise
    raise value.with_traceback(tb)
  File "/Users/eiji/anaconda3/lib/python3.7/site-packages/sqlalchemy/engine/base.py", line 2276, in _wrap_pool_connect
    return fn()
  File "/Users/eiji/anaconda3/lib/python3.7/site-packages/sqlalchemy/pool/base.py", line 363, in connect
    return _ConnectionFairy._checkout(self)
  File "/Users/eiji/anaconda3/lib/python3.7/site-packages/sqlalchemy/pool/base.py", line 760, in _checkout
    fairy = _ConnectionRecord.checkout(pool)
  File "/Users/eiji/anaconda3/lib/python3.7/site-packages/sqlalchemy/pool/base.py", line 492, in checkout
    rec = pool._do_get()
  File "/Users/eiji/anaconda3/lib/python3.7/site-packages/sqlalchemy/pool/impl.py", line 139, in _do_get
    self._dec_overflow()
  File "/Users/eiji/anaconda3/lib/python3.7/site-packages/sqlalchemy/util/langhelpers.py", line 68, in __exit__
    compat.reraise(exc_type, exc_value, exc_tb)
  File "/Users/eiji/anaconda3/lib/python3.7/site-packages/sqlalchemy/util/compat.py", line 153, in reraise
    raise value
  File "/Users/eiji/anaconda3/lib/python3.7/site-packages/sqlalchemy/pool/impl.py", line 136, in _do_get
    return self._create_connection()
  File "/Users/eiji/anaconda3/lib/python3.7/site-packages/sqlalchemy/pool/base.py", line 308, in _create_connection
    return _ConnectionRecord(self)
  File "/Users/eiji/anaconda3/lib/python3.7/site-packages/sqlalchemy/pool/base.py", line 437, in __init__
    self.__connect(first_connect_check=True)
  File "/Users/eiji/anaconda3/lib/python3.7/site-packages/sqlalchemy/pool/base.py", line 639, in __connect
    connection = pool._invoke_creator(self)
  File "/Users/eiji/anaconda3/lib/python3.7/site-packages/sqlalchemy/engine/strategies.py", line 114, in connect
    return dialect.connect(*cargs, **cparams)
  File "/Users/eiji/anaconda3/lib/python3.7/site-packages/sqlalchemy/engine/default.py", line 482, in connect
    return self.dbapi.connect(*cargs, **cparams)
  File "/Users/eiji/anaconda3/lib/python3.7/site-packages/psycopg2/__init__.py", line 126, in connect
    conn = _connect(dsn, connection_factory=connection_factory, **kwasync)
sqlalchemy.exc.OperationalError: (psycopg2.OperationalError) FATAL:  role "amy" does not exist

(Background on this error at: http://sqlalche.me/e/e3q8)
2020-01-05 17:13:19,887 ERROR: Exception on /venues [GET] [in /Users/eiji/anaconda3/lib/python3.7/site-packages/flask/app.py:1780]
Traceback (most recent call last):
  File "/Users/eiji/anaconda3/lib/python3.7/site-packages/sqlalchemy/engine/base.py", line 2276, in _wrap_pool_connect
    return fn()
  File "/Users/eiji/anaconda3/lib/python3.7/site-packages/sqlalchemy/pool/base.py", line 363, in connect
    return _ConnectionFairy._checkout(self)
  File "/Users/eiji/anaconda3/lib/python3.7/site-packages/sqlalchemy/pool/base.py", line 760, in _checkout
    fairy = _ConnectionRecord.checkout(pool)
  File "/Users/eiji/anaconda3/lib/python3.7/site-packages/sqlalchemy/pool/base.py", line 492, in checkout
    rec = pool._do_get()
  File "/Users/eiji/anaconda3/lib/python3.7/site-packages/sqlalchemy/pool/impl.py", line 139, in _do_get
    self._dec_overflow()
  File "/Users/eiji/anaconda3/lib/python3.7/site-packages/sqlalchemy/util/langhelpers.py", line 68, in __exit__
    compat.reraise(exc_type, exc_value, exc_tb)
  File "/Users/eiji/anaconda3/lib/python3.7/site-packages/sqlalchemy/util/compat.py", line 153, in reraise
    raise value
  File "/Users/eiji/anaconda3/lib/python3.7/site-packages/sqlalchemy/pool/impl.py", line 136, in _do_get
    return self._create_connection()
  File "/Users/eiji/anaconda3/lib/python3.7/site-packages/sqlalchemy/pool/base.py", line 308, in _create_connection
    return _ConnectionRecord(self)
  File "/Users/eiji/anaconda3/lib/python3.7/site-packages/sqlalchemy/pool/base.py", line 437, in __init__
    self.__connect(first_connect_check=True)
  File "/Users/eiji/anaconda3/lib/python3.7/site-packages/sqlalchemy/pool/base.py", line 639, in __connect
    connection = pool._invoke_creator(self)
  File "/Users/eiji/anaconda3/lib/python3.7/site-packages/sqlalchemy/engine/strategies.py", line 114, in connect
    return dialect.connect(*cargs, **cparams)
  File "/Users/eiji/anaconda3/lib/python3.7/site-packages/sqlalchemy/engine/default.py", line 482, in connect
    return self.dbapi.connect(*cargs, **cparams)
  File "/Users/eiji/anaconda3/lib/python3.7/site-packages/psycopg2/__init__.py", line 126, in connect
    conn = _connect(dsn, connection_factory=connection_factory, **kwasync)
psycopg2.OperationalError: FATAL:  role "amy" does not exist


The above exception was the direct cause of the following exception:

Traceback (most recent call last):
  File "/Users/eiji/anaconda3/lib/python3.7/site-packages/flask/app.py", line 2311, in wsgi_app
    response = self.full_dispatch_request()
  File "/Users/eiji/anaconda3/lib/python3.7/site-packages/flask/app.py", line 1834, in full_dispatch_request
    rv = self.handle_user_exception(e)
  File "/Users/eiji/anaconda3/lib/python3.7/site-packages/flask/app.py", line 1737, in handle_user_exception
    reraise(exc_type, exc_value, tb)
  File "/Users/eiji/anaconda3/lib/python3.7/site-packages/flask/_compat.py", line 36, in reraise
    raise value
  File "/Users/eiji/anaconda3/lib/python3.7/site-packages/flask/app.py", line 1832, in full_dispatch_request
    rv = self.dispatch_request()
  File "/Users/eiji/anaconda3/lib/python3.7/site-packages/flask/app.py", line 1818, in dispatch_request
    return self.view_functions[rule.endpoint](**req.view_args)
  File "/Users/eiji/Desktop/class-demo/01_fyyur/projects/app.py", line 137, in venues
    )
  File "/Users/eiji/anaconda3/lib/python3.7/site-packages/sqlalchemy/orm/query.py", line 3211, in all
    return list(self)
  File "/Users/eiji/anaconda3/lib/python3.7/site-packages/sqlalchemy/orm/query.py", line 3367, in __iter__
    return self._execute_and_instances(context)
  File "/Users/eiji/anaconda3/lib/python3.7/site-packages/sqlalchemy/orm/query.py", line 3389, in _execute_and_instances
    querycontext, self._connection_from_session, close_with_result=True
  File "/Users/eiji/anaconda3/lib/python3.7/site-packages/sqlalchemy/orm/query.py", line 3404, in _get_bind_args
    mapper=self._bind_mapper(), clause=querycontext.statement, **kw
  File "/Users/eiji/anaconda3/lib/python3.7/site-packages/sqlalchemy/orm/query.py", line 3382, in _connection_from_session
    conn = self.session.connection(**kw)
  File "/Users/eiji/anaconda3/lib/python3.7/site-packages/sqlalchemy/orm/session.py", line 1124, in connection
    execution_options=execution_options,
  File "/Users/eiji/anaconda3/lib/python3.7/site-packages/sqlalchemy/orm/session.py", line 1130, in _connection_for_bind
    engine, execution_options
  File "/Users/eiji/anaconda3/lib/python3.7/site-packages/sqlalchemy/orm/session.py", line 431, in _connection_for_bind
    conn = bind._contextual_connect()
  File "/Users/eiji/anaconda3/lib/python3.7/site-packages/sqlalchemy/engine/base.py", line 2242, in _contextual_connect
    self._wrap_pool_connect(self.pool.connect, None),
  File "/Users/eiji/anaconda3/lib/python3.7/site-packages/sqlalchemy/engine/base.py", line 2280, in _wrap_pool_connect
    e, dialect, self
  File "/Users/eiji/anaconda3/lib/python3.7/site-packages/sqlalchemy/engine/base.py", line 1547, in _handle_dbapi_exception_noconnection
    util.raise_from_cause(sqlalchemy_exception, exc_info)
  File "/Users/eiji/anaconda3/lib/python3.7/site-packages/sqlalchemy/util/compat.py", line 398, in raise_from_cause
    reraise(type(exception), exception, tb=exc_tb, cause=cause)
  File "/Users/eiji/anaconda3/lib/python3.7/site-packages/sqlalchemy/util/compat.py", line 152, in reraise
    raise value.with_traceback(tb)
  File "/Users/eiji/anaconda3/lib/python3.7/site-packages/sqlalchemy/engine/base.py", line 2276, in _wrap_pool_connect
    return fn()
  File "/Users/eiji/anaconda3/lib/python3.7/site-packages/sqlalchemy/pool/base.py", line 363, in connect
    return _ConnectionFairy._checkout(self)
  File "/Users/eiji/anaconda3/lib/python3.7/site-packages/sqlalchemy/pool/base.py", line 760, in _checkout
    fairy = _ConnectionRecord.checkout(pool)
  File "/Users/eiji/anaconda3/lib/python3.7/site-packages/sqlalchemy/pool/base.py", line 492, in checkout
    rec = pool._do_get()
  File "/Users/eiji/anaconda3/lib/python3.7/site-packages/sqlalchemy/pool/impl.py", line 139, in _do_get
    self._dec_overflow()
  File "/Users/eiji/anaconda3/lib/python3.7/site-packages/sqlalchemy/util/langhelpers.py", line 68, in __exit__
    compat.reraise(exc_type, exc_value, exc_tb)
  File "/Users/eiji/anaconda3/lib/python3.7/site-packages/sqlalchemy/util/compat.py", line 153, in reraise
    raise value
  File "/Users/eiji/anaconda3/lib/python3.7/site-packages/sqlalchemy/pool/impl.py", line 136, in _do_get
    return self._create_connection()
  File "/Users/eiji/anaconda3/lib/python3.7/site-packages/sqlalchemy/pool/base.py", line 308, in _create_connection
    return _ConnectionRecord(self)
  File "/Users/eiji/anaconda3/lib/python3.7/site-packages/sqlalchemy/pool/base.py", line 437, in __init__
    self.__connect(first_connect_check=True)
  File "/Users/eiji/anaconda3/lib/python3.7/site-packages/sqlalchemy/pool/base.py", line 639, in __connect
    connection = pool._invoke_creator(self)
  File "/Users/eiji/anaconda3/lib/python3.7/site-packages/sqlalchemy/engine/strategies.py", line 114, in connect
    return dialect.connect(*cargs, **cparams)
  File "/Users/eiji/anaconda3/lib/python3.7/site-packages/sqlalchemy/engine/default.py", line 482, in connect
    return self.dbapi.connect(*cargs, **cparams)
  File "/Users/eiji/anaconda3/lib/python3.7/site-packages/psycopg2/__init__.py", line 126, in connect
    conn = _connect(dsn, connection_factory=connection_factory, **kwasync)
sqlalchemy.exc.OperationalError: (psycopg2.OperationalError) FATAL:  role "amy" does not exist

(Background on this error at: http://sqlalche.me/e/e3q8)
2020-01-05 17:13:30,878 ERROR: Exception on /venues [GET] [in /Users/eiji/anaconda3/lib/python3.7/site-packages/flask/app.py:1780]
Traceback (most recent call last):
  File "/Users/eiji/anaconda3/lib/python3.7/site-packages/sqlalchemy/engine/base.py", line 2276, in _wrap_pool_connect
    return fn()
  File "/Users/eiji/anaconda3/lib/python3.7/site-packages/sqlalchemy/pool/base.py", line 363, in connect
    return _ConnectionFairy._checkout(self)
  File "/Users/eiji/anaconda3/lib/python3.7/site-packages/sqlalchemy/pool/base.py", line 760, in _checkout
    fairy = _ConnectionRecord.checkout(pool)
  File "/Users/eiji/anaconda3/lib/python3.7/site-packages/sqlalchemy/pool/base.py", line 492, in checkout
    rec = pool._do_get()
  File "/Users/eiji/anaconda3/lib/python3.7/site-packages/sqlalchemy/pool/impl.py", line 139, in _do_get
    self._dec_overflow()
  File "/Users/eiji/anaconda3/lib/python3.7/site-packages/sqlalchemy/util/langhelpers.py", line 68, in __exit__
    compat.reraise(exc_type, exc_value, exc_tb)
  File "/Users/eiji/anaconda3/lib/python3.7/site-packages/sqlalchemy/util/compat.py", line 153, in reraise
    raise value
  File "/Users/eiji/anaconda3/lib/python3.7/site-packages/sqlalchemy/pool/impl.py", line 136, in _do_get
    return self._create_connection()
  File "/Users/eiji/anaconda3/lib/python3.7/site-packages/sqlalchemy/pool/base.py", line 308, in _create_connection
    return _ConnectionRecord(self)
  File "/Users/eiji/anaconda3/lib/python3.7/site-packages/sqlalchemy/pool/base.py", line 437, in __init__
    self.__connect(first_connect_check=True)
  File "/Users/eiji/anaconda3/lib/python3.7/site-packages/sqlalchemy/pool/base.py", line 639, in __connect
    connection = pool._invoke_creator(self)
  File "/Users/eiji/anaconda3/lib/python3.7/site-packages/sqlalchemy/engine/strategies.py", line 114, in connect
    return dialect.connect(*cargs, **cparams)
  File "/Users/eiji/anaconda3/lib/python3.7/site-packages/sqlalchemy/engine/default.py", line 482, in connect
    return self.dbapi.connect(*cargs, **cparams)
  File "/Users/eiji/anaconda3/lib/python3.7/site-packages/psycopg2/__init__.py", line 126, in connect
    conn = _connect(dsn, connection_factory=connection_factory, **kwasync)
psycopg2.OperationalError: FATAL:  role "amy" does not exist


The above exception was the direct cause of the following exception:

Traceback (most recent call last):
  File "/Users/eiji/anaconda3/lib/python3.7/site-packages/flask/app.py", line 2311, in wsgi_app
    response = self.full_dispatch_request()
  File "/Users/eiji/anaconda3/lib/python3.7/site-packages/flask/app.py", line 1834, in full_dispatch_request
    rv = self.handle_user_exception(e)
  File "/Users/eiji/anaconda3/lib/python3.7/site-packages/flask/app.py", line 1737, in handle_user_exception
    reraise(exc_type, exc_value, tb)
  File "/Users/eiji/anaconda3/lib/python3.7/site-packages/flask/_compat.py", line 36, in reraise
    raise value
  File "/Users/eiji/anaconda3/lib/python3.7/site-packages/flask/app.py", line 1832, in full_dispatch_request
    rv = self.dispatch_request()
  File "/Users/eiji/anaconda3/lib/python3.7/site-packages/flask/app.py", line 1818, in dispatch_request
    return self.view_functions[rule.endpoint](**req.view_args)
  File "/Users/eiji/Desktop/class-demo/01_fyyur/projects/app.py", line 137, in venues
    )
  File "/Users/eiji/anaconda3/lib/python3.7/site-packages/sqlalchemy/orm/query.py", line 3211, in all
    return list(self)
  File "/Users/eiji/anaconda3/lib/python3.7/site-packages/sqlalchemy/orm/query.py", line 3367, in __iter__
    return self._execute_and_instances(context)
  File "/Users/eiji/anaconda3/lib/python3.7/site-packages/sqlalchemy/orm/query.py", line 3389, in _execute_and_instances
    querycontext, self._connection_from_session, close_with_result=True
  File "/Users/eiji/anaconda3/lib/python3.7/site-packages/sqlalchemy/orm/query.py", line 3404, in _get_bind_args
    mapper=self._bind_mapper(), clause=querycontext.statement, **kw
  File "/Users/eiji/anaconda3/lib/python3.7/site-packages/sqlalchemy/orm/query.py", line 3382, in _connection_from_session
    conn = self.session.connection(**kw)
  File "/Users/eiji/anaconda3/lib/python3.7/site-packages/sqlalchemy/orm/session.py", line 1124, in connection
    execution_options=execution_options,
  File "/Users/eiji/anaconda3/lib/python3.7/site-packages/sqlalchemy/orm/session.py", line 1130, in _connection_for_bind
    engine, execution_options
  File "/Users/eiji/anaconda3/lib/python3.7/site-packages/sqlalchemy/orm/session.py", line 431, in _connection_for_bind
    conn = bind._contextual_connect()
  File "/Users/eiji/anaconda3/lib/python3.7/site-packages/sqlalchemy/engine/base.py", line 2242, in _contextual_connect
    self._wrap_pool_connect(self.pool.connect, None),
  File "/Users/eiji/anaconda3/lib/python3.7/site-packages/sqlalchemy/engine/base.py", line 2280, in _wrap_pool_connect
    e, dialect, self
  File "/Users/eiji/anaconda3/lib/python3.7/site-packages/sqlalchemy/engine/base.py", line 1547, in _handle_dbapi_exception_noconnection
    util.raise_from_cause(sqlalchemy_exception, exc_info)
  File "/Users/eiji/anaconda3/lib/python3.7/site-packages/sqlalchemy/util/compat.py", line 398, in raise_from_cause
    reraise(type(exception), exception, tb=exc_tb, cause=cause)
  File "/Users/eiji/anaconda3/lib/python3.7/site-packages/sqlalchemy/util/compat.py", line 152, in reraise
    raise value.with_traceback(tb)
  File "/Users/eiji/anaconda3/lib/python3.7/site-packages/sqlalchemy/engine/base.py", line 2276, in _wrap_pool_connect
    return fn()
  File "/Users/eiji/anaconda3/lib/python3.7/site-packages/sqlalchemy/pool/base.py", line 363, in connect
    return _ConnectionFairy._checkout(self)
  File "/Users/eiji/anaconda3/lib/python3.7/site-packages/sqlalchemy/pool/base.py", line 760, in _checkout
    fairy = _ConnectionRecord.checkout(pool)
  File "/Users/eiji/anaconda3/lib/python3.7/site-packages/sqlalchemy/pool/base.py", line 492, in checkout
    rec = pool._do_get()
  File "/Users/eiji/anaconda3/lib/python3.7/site-packages/sqlalchemy/pool/impl.py", line 139, in _do_get
    self._dec_overflow()
  File "/Users/eiji/anaconda3/lib/python3.7/site-packages/sqlalchemy/util/langhelpers.py", line 68, in __exit__
    compat.reraise(exc_type, exc_value, exc_tb)
  File "/Users/eiji/anaconda3/lib/python3.7/site-packages/sqlalchemy/util/compat.py", line 153, in reraise
    raise value
  File "/Users/eiji/anaconda3/lib/python3.7/site-packages/sqlalchemy/pool/impl.py", line 136, in _do_get
    return self._create_connection()
  File "/Users/eiji/anaconda3/lib/python3.7/site-packages/sqlalchemy/pool/base.py", line 308, in _create_connection
    return _ConnectionRecord(self)
  File "/Users/eiji/anaconda3/lib/python3.7/site-packages/sqlalchemy/pool/base.py", line 437, in __init__
    self.__connect(first_connect_check=True)
  File "/Users/eiji/anaconda3/lib/python3.7/site-packages/sqlalchemy/pool/base.py", line 639, in __connect
    connection = pool._invoke_creator(self)
  File "/Users/eiji/anaconda3/lib/python3.7/site-packages/sqlalchemy/engine/strategies.py", line 114, in connect
    return dialect.connect(*cargs, **cparams)
  File "/Users/eiji/anaconda3/lib/python3.7/site-packages/sqlalchemy/engine/default.py", line 482, in connect
    return self.dbapi.connect(*cargs, **cparams)
  File "/Users/eiji/anaconda3/lib/python3.7/site-packages/psycopg2/__init__.py", line 126, in connect
    conn = _connect(dsn, connection_factory=connection_factory, **kwasync)
sqlalchemy.exc.OperationalError: (psycopg2.OperationalError) FATAL:  role "amy" does not exist

(Background on this error at: http://sqlalche.me/e/e3q8)
2020-01-05 17:14:07,753 ERROR: Exception on /venues [GET] [in /Users/eiji/anaconda3/lib/python3.7/site-packages/flask/app.py:1780]
Traceback (most recent call last):
  File "/Users/eiji/anaconda3/lib/python3.7/site-packages/sqlalchemy/engine/base.py", line 2276, in _wrap_pool_connect
    return fn()
  File "/Users/eiji/anaconda3/lib/python3.7/site-packages/sqlalchemy/pool/base.py", line 363, in connect
    return _ConnectionFairy._checkout(self)
  File "/Users/eiji/anaconda3/lib/python3.7/site-packages/sqlalchemy/pool/base.py", line 760, in _checkout
    fairy = _ConnectionRecord.checkout(pool)
  File "/Users/eiji/anaconda3/lib/python3.7/site-packages/sqlalchemy/pool/base.py", line 492, in checkout
    rec = pool._do_get()
  File "/Users/eiji/anaconda3/lib/python3.7/site-packages/sqlalchemy/pool/impl.py", line 139, in _do_get
    self._dec_overflow()
  File "/Users/eiji/anaconda3/lib/python3.7/site-packages/sqlalchemy/util/langhelpers.py", line 68, in __exit__
    compat.reraise(exc_type, exc_value, exc_tb)
  File "/Users/eiji/anaconda3/lib/python3.7/site-packages/sqlalchemy/util/compat.py", line 153, in reraise
    raise value
  File "/Users/eiji/anaconda3/lib/python3.7/site-packages/sqlalchemy/pool/impl.py", line 136, in _do_get
    return self._create_connection()
  File "/Users/eiji/anaconda3/lib/python3.7/site-packages/sqlalchemy/pool/base.py", line 308, in _create_connection
    return _ConnectionRecord(self)
  File "/Users/eiji/anaconda3/lib/python3.7/site-packages/sqlalchemy/pool/base.py", line 437, in __init__
    self.__connect(first_connect_check=True)
  File "/Users/eiji/anaconda3/lib/python3.7/site-packages/sqlalchemy/pool/base.py", line 639, in __connect
    connection = pool._invoke_creator(self)
  File "/Users/eiji/anaconda3/lib/python3.7/site-packages/sqlalchemy/engine/strategies.py", line 114, in connect
    return dialect.connect(*cargs, **cparams)
  File "/Users/eiji/anaconda3/lib/python3.7/site-packages/sqlalchemy/engine/default.py", line 482, in connect
    return self.dbapi.connect(*cargs, **cparams)
  File "/Users/eiji/anaconda3/lib/python3.7/site-packages/psycopg2/__init__.py", line 126, in connect
    conn = _connect(dsn, connection_factory=connection_factory, **kwasync)
psycopg2.OperationalError: FATAL:  role "amy" does not exist


The above exception was the direct cause of the following exception:

Traceback (most recent call last):
  File "/Users/eiji/anaconda3/lib/python3.7/site-packages/flask/app.py", line 2311, in wsgi_app
    response = self.full_dispatch_request()
  File "/Users/eiji/anaconda3/lib/python3.7/site-packages/flask/app.py", line 1834, in full_dispatch_request
    rv = self.handle_user_exception(e)
  File "/Users/eiji/anaconda3/lib/python3.7/site-packages/flask/app.py", line 1737, in handle_user_exception
    reraise(exc_type, exc_value, tb)
  File "/Users/eiji/anaconda3/lib/python3.7/site-packages/flask/_compat.py", line 36, in reraise
    raise value
  File "/Users/eiji/anaconda3/lib/python3.7/site-packages/flask/app.py", line 1832, in full_dispatch_request
    rv = self.dispatch_request()
  File "/Users/eiji/anaconda3/lib/python3.7/site-packages/flask/app.py", line 1818, in dispatch_request
    return self.view_functions[rule.endpoint](**req.view_args)
  File "/Users/eiji/Desktop/class-demo/01_fyyur/projects/app.py", line 137, in venues
    )
  File "/Users/eiji/anaconda3/lib/python3.7/site-packages/sqlalchemy/orm/query.py", line 3211, in all
    return list(self)
  File "/Users/eiji/anaconda3/lib/python3.7/site-packages/sqlalchemy/orm/query.py", line 3367, in __iter__
    return self._execute_and_instances(context)
  File "/Users/eiji/anaconda3/lib/python3.7/site-packages/sqlalchemy/orm/query.py", line 3389, in _execute_and_instances
    querycontext, self._connection_from_session, close_with_result=True
  File "/Users/eiji/anaconda3/lib/python3.7/site-packages/sqlalchemy/orm/query.py", line 3404, in _get_bind_args
    mapper=self._bind_mapper(), clause=querycontext.statement, **kw
  File "/Users/eiji/anaconda3/lib/python3.7/site-packages/sqlalchemy/orm/query.py", line 3382, in _connection_from_session
    conn = self.session.connection(**kw)
  File "/Users/eiji/anaconda3/lib/python3.7/site-packages/sqlalchemy/orm/session.py", line 1124, in connection
    execution_options=execution_options,
  File "/Users/eiji/anaconda3/lib/python3.7/site-packages/sqlalchemy/orm/session.py", line 1130, in _connection_for_bind
    engine, execution_options
  File "/Users/eiji/anaconda3/lib/python3.7/site-packages/sqlalchemy/orm/session.py", line 431, in _connection_for_bind
    conn = bind._contextual_connect()
  File "/Users/eiji/anaconda3/lib/python3.7/site-packages/sqlalchemy/engine/base.py", line 2242, in _contextual_connect
    self._wrap_pool_connect(self.pool.connect, None),
  File "/Users/eiji/anaconda3/lib/python3.7/site-packages/sqlalchemy/engine/base.py", line 2280, in _wrap_pool_connect
    e, dialect, self
  File "/Users/eiji/anaconda3/lib/python3.7/site-packages/sqlalchemy/engine/base.py", line 1547, in _handle_dbapi_exception_noconnection
    util.raise_from_cause(sqlalchemy_exception, exc_info)
  File "/Users/eiji/anaconda3/lib/python3.7/site-packages/sqlalchemy/util/compat.py", line 398, in raise_from_cause
    reraise(type(exception), exception, tb=exc_tb, cause=cause)
  File "/Users/eiji/anaconda3/lib/python3.7/site-packages/sqlalchemy/util/compat.py", line 152, in reraise
    raise value.with_traceback(tb)
  File "/Users/eiji/anaconda3/lib/python3.7/site-packages/sqlalchemy/engine/base.py", line 2276, in _wrap_pool_connect
    return fn()
  File "/Users/eiji/anaconda3/lib/python3.7/site-packages/sqlalchemy/pool/base.py", line 363, in connect
    return _ConnectionFairy._checkout(self)
  File "/Users/eiji/anaconda3/lib/python3.7/site-packages/sqlalchemy/pool/base.py", line 760, in _checkout
    fairy = _ConnectionRecord.checkout(pool)
  File "/Users/eiji/anaconda3/lib/python3.7/site-packages/sqlalchemy/pool/base.py", line 492, in checkout
    rec = pool._do_get()
  File "/Users/eiji/anaconda3/lib/python3.7/site-packages/sqlalchemy/pool/impl.py", line 139, in _do_get
    self._dec_overflow()
  File "/Users/eiji/anaconda3/lib/python3.7/site-packages/sqlalchemy/util/langhelpers.py", line 68, in __exit__
    compat.reraise(exc_type, exc_value, exc_tb)
  File "/Users/eiji/anaconda3/lib/python3.7/site-packages/sqlalchemy/util/compat.py", line 153, in reraise
    raise value
  File "/Users/eiji/anaconda3/lib/python3.7/site-packages/sqlalchemy/pool/impl.py", line 136, in _do_get
    return self._create_connection()
  File "/Users/eiji/anaconda3/lib/python3.7/site-packages/sqlalchemy/pool/base.py", line 308, in _create_connection
    return _ConnectionRecord(self)
  File "/Users/eiji/anaconda3/lib/python3.7/site-packages/sqlalchemy/pool/base.py", line 437, in __init__
    self.__connect(first_connect_check=True)
  File "/Users/eiji/anaconda3/lib/python3.7/site-packages/sqlalchemy/pool/base.py", line 639, in __connect
    connection = pool._invoke_creator(self)
  File "/Users/eiji/anaconda3/lib/python3.7/site-packages/sqlalchemy/engine/strategies.py", line 114, in connect
    return dialect.connect(*cargs, **cparams)
  File "/Users/eiji/anaconda3/lib/python3.7/site-packages/sqlalchemy/engine/default.py", line 482, in connect
    return self.dbapi.connect(*cargs, **cparams)
  File "/Users/eiji/anaconda3/lib/python3.7/site-packages/psycopg2/__init__.py", line 126, in connect
    conn = _connect(dsn, connection_factory=connection_factory, **kwasync)
sqlalchemy.exc.OperationalError: (psycopg2.OperationalError) FATAL:  role "amy" does not exist

(Background on this error at: http://sqlalche.me/e/e3q8)
2020-01-05 17:14:09,004 ERROR: Exception on /venues [GET] [in /Users/eiji/anaconda3/lib/python3.7/site-packages/flask/app.py:1780]
Traceback (most recent call last):
  File "/Users/eiji/anaconda3/lib/python3.7/site-packages/sqlalchemy/engine/base.py", line 2276, in _wrap_pool_connect
    return fn()
  File "/Users/eiji/anaconda3/lib/python3.7/site-packages/sqlalchemy/pool/base.py", line 363, in connect
    return _ConnectionFairy._checkout(self)
  File "/Users/eiji/anaconda3/lib/python3.7/site-packages/sqlalchemy/pool/base.py", line 760, in _checkout
    fairy = _ConnectionRecord.checkout(pool)
  File "/Users/eiji/anaconda3/lib/python3.7/site-packages/sqlalchemy/pool/base.py", line 492, in checkout
    rec = pool._do_get()
  File "/Users/eiji/anaconda3/lib/python3.7/site-packages/sqlalchemy/pool/impl.py", line 139, in _do_get
    self._dec_overflow()
  File "/Users/eiji/anaconda3/lib/python3.7/site-packages/sqlalchemy/util/langhelpers.py", line 68, in __exit__
    compat.reraise(exc_type, exc_value, exc_tb)
  File "/Users/eiji/anaconda3/lib/python3.7/site-packages/sqlalchemy/util/compat.py", line 153, in reraise
    raise value
  File "/Users/eiji/anaconda3/lib/python3.7/site-packages/sqlalchemy/pool/impl.py", line 136, in _do_get
    return self._create_connection()
  File "/Users/eiji/anaconda3/lib/python3.7/site-packages/sqlalchemy/pool/base.py", line 308, in _create_connection
    return _ConnectionRecord(self)
  File "/Users/eiji/anaconda3/lib/python3.7/site-packages/sqlalchemy/pool/base.py", line 437, in __init__
    self.__connect(first_connect_check=True)
  File "/Users/eiji/anaconda3/lib/python3.7/site-packages/sqlalchemy/pool/base.py", line 639, in __connect
    connection = pool._invoke_creator(self)
  File "/Users/eiji/anaconda3/lib/python3.7/site-packages/sqlalchemy/engine/strategies.py", line 114, in connect
    return dialect.connect(*cargs, **cparams)
  File "/Users/eiji/anaconda3/lib/python3.7/site-packages/sqlalchemy/engine/default.py", line 482, in connect
    return self.dbapi.connect(*cargs, **cparams)
  File "/Users/eiji/anaconda3/lib/python3.7/site-packages/psycopg2/__init__.py", line 126, in connect
    conn = _connect(dsn, connection_factory=connection_factory, **kwasync)
psycopg2.OperationalError: FATAL:  role "amy" does not exist


The above exception was the direct cause of the following exception:

Traceback (most recent call last):
  File "/Users/eiji/anaconda3/lib/python3.7/site-packages/flask/app.py", line 2311, in wsgi_app
    response = self.full_dispatch_request()
  File "/Users/eiji/anaconda3/lib/python3.7/site-packages/flask/app.py", line 1834, in full_dispatch_request
    rv = self.handle_user_exception(e)
  File "/Users/eiji/anaconda3/lib/python3.7/site-packages/flask/app.py", line 1737, in handle_user_exception
    reraise(exc_type, exc_value, tb)
  File "/Users/eiji/anaconda3/lib/python3.7/site-packages/flask/_compat.py", line 36, in reraise
    raise value
  File "/Users/eiji/anaconda3/lib/python3.7/site-packages/flask/app.py", line 1832, in full_dispatch_request
    rv = self.dispatch_request()
  File "/Users/eiji/anaconda3/lib/python3.7/site-packages/flask/app.py", line 1818, in dispatch_request
    return self.view_functions[rule.endpoint](**req.view_args)
  File "/Users/eiji/Desktop/class-demo/01_fyyur/projects/app.py", line 137, in venues
    )
  File "/Users/eiji/anaconda3/lib/python3.7/site-packages/sqlalchemy/orm/query.py", line 3211, in all
    return list(self)
  File "/Users/eiji/anaconda3/lib/python3.7/site-packages/sqlalchemy/orm/query.py", line 3367, in __iter__
    return self._execute_and_instances(context)
  File "/Users/eiji/anaconda3/lib/python3.7/site-packages/sqlalchemy/orm/query.py", line 3389, in _execute_and_instances
    querycontext, self._connection_from_session, close_with_result=True
  File "/Users/eiji/anaconda3/lib/python3.7/site-packages/sqlalchemy/orm/query.py", line 3404, in _get_bind_args
    mapper=self._bind_mapper(), clause=querycontext.statement, **kw
  File "/Users/eiji/anaconda3/lib/python3.7/site-packages/sqlalchemy/orm/query.py", line 3382, in _connection_from_session
    conn = self.session.connection(**kw)
  File "/Users/eiji/anaconda3/lib/python3.7/site-packages/sqlalchemy/orm/session.py", line 1124, in connection
    execution_options=execution_options,
  File "/Users/eiji/anaconda3/lib/python3.7/site-packages/sqlalchemy/orm/session.py", line 1130, in _connection_for_bind
    engine, execution_options
  File "/Users/eiji/anaconda3/lib/python3.7/site-packages/sqlalchemy/orm/session.py", line 431, in _connection_for_bind
    conn = bind._contextual_connect()
  File "/Users/eiji/anaconda3/lib/python3.7/site-packages/sqlalchemy/engine/base.py", line 2242, in _contextual_connect
    self._wrap_pool_connect(self.pool.connect, None),
  File "/Users/eiji/anaconda3/lib/python3.7/site-packages/sqlalchemy/engine/base.py", line 2280, in _wrap_pool_connect
    e, dialect, self
  File "/Users/eiji/anaconda3/lib/python3.7/site-packages/sqlalchemy/engine/base.py", line 1547, in _handle_dbapi_exception_noconnection
    util.raise_from_cause(sqlalchemy_exception, exc_info)
  File "/Users/eiji/anaconda3/lib/python3.7/site-packages/sqlalchemy/util/compat.py", line 398, in raise_from_cause
    reraise(type(exception), exception, tb=exc_tb, cause=cause)
  File "/Users/eiji/anaconda3/lib/python3.7/site-packages/sqlalchemy/util/compat.py", line 152, in reraise
    raise value.with_traceback(tb)
  File "/Users/eiji/anaconda3/lib/python3.7/site-packages/sqlalchemy/engine/base.py", line 2276, in _wrap_pool_connect
    return fn()
  File "/Users/eiji/anaconda3/lib/python3.7/site-packages/sqlalchemy/pool/base.py", line 363, in connect
    return _ConnectionFairy._checkout(self)
  File "/Users/eiji/anaconda3/lib/python3.7/site-packages/sqlalchemy/pool/base.py", line 760, in _checkout
    fairy = _ConnectionRecord.checkout(pool)
  File "/Users/eiji/anaconda3/lib/python3.7/site-packages/sqlalchemy/pool/base.py", line 492, in checkout
    rec = pool._do_get()
  File "/Users/eiji/anaconda3/lib/python3.7/site-packages/sqlalchemy/pool/impl.py", line 139, in _do_get
    self._dec_overflow()
  File "/Users/eiji/anaconda3/lib/python3.7/site-packages/sqlalchemy/util/langhelpers.py", line 68, in __exit__
    compat.reraise(exc_type, exc_value, exc_tb)
  File "/Users/eiji/anaconda3/lib/python3.7/site-packages/sqlalchemy/util/compat.py", line 153, in reraise
    raise value
  File "/Users/eiji/anaconda3/lib/python3.7/site-packages/sqlalchemy/pool/impl.py", line 136, in _do_get
    return self._create_connection()
  File "/Users/eiji/anaconda3/lib/python3.7/site-packages/sqlalchemy/pool/base.py", line 308, in _create_connection
    return _ConnectionRecord(self)
  File "/Users/eiji/anaconda3/lib/python3.7/site-packages/sqlalchemy/pool/base.py", line 437, in __init__
    self.__connect(first_connect_check=True)
  File "/Users/eiji/anaconda3/lib/python3.7/site-packages/sqlalchemy/pool/base.py", line 639, in __connect
    connection = pool._invoke_creator(self)
  File "/Users/eiji/anaconda3/lib/python3.7/site-packages/sqlalchemy/engine/strategies.py", line 114, in connect
    return dialect.connect(*cargs, **cparams)
  File "/Users/eiji/anaconda3/lib/python3.7/site-packages/sqlalchemy/engine/default.py", line 482, in connect
    return self.dbapi.connect(*cargs, **cparams)
  File "/Users/eiji/anaconda3/lib/python3.7/site-packages/psycopg2/__init__.py", line 126, in connect
    conn = _connect(dsn, connection_factory=connection_factory, **kwasync)
sqlalchemy.exc.OperationalError: (psycopg2.OperationalError) FATAL:  role "amy" does not exist

(Background on this error at: http://sqlalche.me/e/e3q8)
2020-01-05 17:14:30,856 ERROR: Exception on /venues [GET] [in /Users/eiji/anaconda3/lib/python3.7/site-packages/flask/app.py:1780]
Traceback (most recent call last):
  File "/Users/eiji/anaconda3/lib/python3.7/site-packages/sqlalchemy/engine/base.py", line 2276, in _wrap_pool_connect
    return fn()
  File "/Users/eiji/anaconda3/lib/python3.7/site-packages/sqlalchemy/pool/base.py", line 363, in connect
    return _ConnectionFairy._checkout(self)
  File "/Users/eiji/anaconda3/lib/python3.7/site-packages/sqlalchemy/pool/base.py", line 760, in _checkout
    fairy = _ConnectionRecord.checkout(pool)
  File "/Users/eiji/anaconda3/lib/python3.7/site-packages/sqlalchemy/pool/base.py", line 492, in checkout
    rec = pool._do_get()
  File "/Users/eiji/anaconda3/lib/python3.7/site-packages/sqlalchemy/pool/impl.py", line 139, in _do_get
    self._dec_overflow()
  File "/Users/eiji/anaconda3/lib/python3.7/site-packages/sqlalchemy/util/langhelpers.py", line 68, in __exit__
    compat.reraise(exc_type, exc_value, exc_tb)
  File "/Users/eiji/anaconda3/lib/python3.7/site-packages/sqlalchemy/util/compat.py", line 153, in reraise
    raise value
  File "/Users/eiji/anaconda3/lib/python3.7/site-packages/sqlalchemy/pool/impl.py", line 136, in _do_get
    return self._create_connection()
  File "/Users/eiji/anaconda3/lib/python3.7/site-packages/sqlalchemy/pool/base.py", line 308, in _create_connection
    return _ConnectionRecord(self)
  File "/Users/eiji/anaconda3/lib/python3.7/site-packages/sqlalchemy/pool/base.py", line 437, in __init__
    self.__connect(first_connect_check=True)
  File "/Users/eiji/anaconda3/lib/python3.7/site-packages/sqlalchemy/pool/base.py", line 639, in __connect
    connection = pool._invoke_creator(self)
  File "/Users/eiji/anaconda3/lib/python3.7/site-packages/sqlalchemy/engine/strategies.py", line 114, in connect
    return dialect.connect(*cargs, **cparams)
  File "/Users/eiji/anaconda3/lib/python3.7/site-packages/sqlalchemy/engine/default.py", line 482, in connect
    return self.dbapi.connect(*cargs, **cparams)
  File "/Users/eiji/anaconda3/lib/python3.7/site-packages/psycopg2/__init__.py", line 126, in connect
    conn = _connect(dsn, connection_factory=connection_factory, **kwasync)
psycopg2.OperationalError: FATAL:  role "amy" does not exist


The above exception was the direct cause of the following exception:

Traceback (most recent call last):
  File "/Users/eiji/anaconda3/lib/python3.7/site-packages/flask/app.py", line 2311, in wsgi_app
    response = self.full_dispatch_request()
  File "/Users/eiji/anaconda3/lib/python3.7/site-packages/flask/app.py", line 1834, in full_dispatch_request
    rv = self.handle_user_exception(e)
  File "/Users/eiji/anaconda3/lib/python3.7/site-packages/flask/app.py", line 1737, in handle_user_exception
    reraise(exc_type, exc_value, tb)
  File "/Users/eiji/anaconda3/lib/python3.7/site-packages/flask/_compat.py", line 36, in reraise
    raise value
  File "/Users/eiji/anaconda3/lib/python3.7/site-packages/flask/app.py", line 1832, in full_dispatch_request
    rv = self.dispatch_request()
  File "/Users/eiji/anaconda3/lib/python3.7/site-packages/flask/app.py", line 1818, in dispatch_request
    return self.view_functions[rule.endpoint](**req.view_args)
  File "/Users/eiji/Desktop/class-demo/01_fyyur/projects/app.py", line 137, in venues
    )
  File "/Users/eiji/anaconda3/lib/python3.7/site-packages/sqlalchemy/orm/query.py", line 3211, in all
    return list(self)
  File "/Users/eiji/anaconda3/lib/python3.7/site-packages/sqlalchemy/orm/query.py", line 3367, in __iter__
    return self._execute_and_instances(context)
  File "/Users/eiji/anaconda3/lib/python3.7/site-packages/sqlalchemy/orm/query.py", line 3389, in _execute_and_instances
    querycontext, self._connection_from_session, close_with_result=True
  File "/Users/eiji/anaconda3/lib/python3.7/site-packages/sqlalchemy/orm/query.py", line 3404, in _get_bind_args
    mapper=self._bind_mapper(), clause=querycontext.statement, **kw
  File "/Users/eiji/anaconda3/lib/python3.7/site-packages/sqlalchemy/orm/query.py", line 3382, in _connection_from_session
    conn = self.session.connection(**kw)
  File "/Users/eiji/anaconda3/lib/python3.7/site-packages/sqlalchemy/orm/session.py", line 1124, in connection
    execution_options=execution_options,
  File "/Users/eiji/anaconda3/lib/python3.7/site-packages/sqlalchemy/orm/session.py", line 1130, in _connection_for_bind
    engine, execution_options
  File "/Users/eiji/anaconda3/lib/python3.7/site-packages/sqlalchemy/orm/session.py", line 431, in _connection_for_bind
    conn = bind._contextual_connect()
  File "/Users/eiji/anaconda3/lib/python3.7/site-packages/sqlalchemy/engine/base.py", line 2242, in _contextual_connect
    self._wrap_pool_connect(self.pool.connect, None),
  File "/Users/eiji/anaconda3/lib/python3.7/site-packages/sqlalchemy/engine/base.py", line 2280, in _wrap_pool_connect
    e, dialect, self
  File "/Users/eiji/anaconda3/lib/python3.7/site-packages/sqlalchemy/engine/base.py", line 1547, in _handle_dbapi_exception_noconnection
    util.raise_from_cause(sqlalchemy_exception, exc_info)
  File "/Users/eiji/anaconda3/lib/python3.7/site-packages/sqlalchemy/util/compat.py", line 398, in raise_from_cause
    reraise(type(exception), exception, tb=exc_tb, cause=cause)
  File "/Users/eiji/anaconda3/lib/python3.7/site-packages/sqlalchemy/util/compat.py", line 152, in reraise
    raise value.with_traceback(tb)
  File "/Users/eiji/anaconda3/lib/python3.7/site-packages/sqlalchemy/engine/base.py", line 2276, in _wrap_pool_connect
    return fn()
  File "/Users/eiji/anaconda3/lib/python3.7/site-packages/sqlalchemy/pool/base.py", line 363, in connect
    return _ConnectionFairy._checkout(self)
  File "/Users/eiji/anaconda3/lib/python3.7/site-packages/sqlalchemy/pool/base.py", line 760, in _checkout
    fairy = _ConnectionRecord.checkout(pool)
  File "/Users/eiji/anaconda3/lib/python3.7/site-packages/sqlalchemy/pool/base.py", line 492, in checkout
    rec = pool._do_get()
  File "/Users/eiji/anaconda3/lib/python3.7/site-packages/sqlalchemy/pool/impl.py", line 139, in _do_get
    self._dec_overflow()
  File "/Users/eiji/anaconda3/lib/python3.7/site-packages/sqlalchemy/util/langhelpers.py", line 68, in __exit__
    compat.reraise(exc_type, exc_value, exc_tb)
  File "/Users/eiji/anaconda3/lib/python3.7/site-packages/sqlalchemy/util/compat.py", line 153, in reraise
    raise value
  File "/Users/eiji/anaconda3/lib/python3.7/site-packages/sqlalchemy/pool/impl.py", line 136, in _do_get
    return self._create_connection()
  File "/Users/eiji/anaconda3/lib/python3.7/site-packages/sqlalchemy/pool/base.py", line 308, in _create_connection
    return _ConnectionRecord(self)
  File "/Users/eiji/anaconda3/lib/python3.7/site-packages/sqlalchemy/pool/base.py", line 437, in __init__
    self.__connect(first_connect_check=True)
  File "/Users/eiji/anaconda3/lib/python3.7/site-packages/sqlalchemy/pool/base.py", line 639, in __connect
    connection = pool._invoke_creator(self)
  File "/Users/eiji/anaconda3/lib/python3.7/site-packages/sqlalchemy/engine/strategies.py", line 114, in connect
    return dialect.connect(*cargs, **cparams)
  File "/Users/eiji/anaconda3/lib/python3.7/site-packages/sqlalchemy/engine/default.py", line 482, in connect
    return self.dbapi.connect(*cargs, **cparams)
  File "/Users/eiji/anaconda3/lib/python3.7/site-packages/psycopg2/__init__.py", line 126, in connect
    conn = _connect(dsn, connection_factory=connection_factory, **kwasync)
sqlalchemy.exc.OperationalError: (psycopg2.OperationalError) FATAL:  role "amy" does not exist

(Background on this error at: http://sqlalche.me/e/e3q8)
2020-01-05 17:14:33,489 ERROR: Exception on /venues [GET] [in /Users/eiji/anaconda3/lib/python3.7/site-packages/flask/app.py:1780]
Traceback (most recent call last):
  File "/Users/eiji/anaconda3/lib/python3.7/site-packages/sqlalchemy/engine/base.py", line 2276, in _wrap_pool_connect
    return fn()
  File "/Users/eiji/anaconda3/lib/python3.7/site-packages/sqlalchemy/pool/base.py", line 363, in connect
    return _ConnectionFairy._checkout(self)
  File "/Users/eiji/anaconda3/lib/python3.7/site-packages/sqlalchemy/pool/base.py", line 760, in _checkout
    fairy = _ConnectionRecord.checkout(pool)
  File "/Users/eiji/anaconda3/lib/python3.7/site-packages/sqlalchemy/pool/base.py", line 492, in checkout
    rec = pool._do_get()
  File "/Users/eiji/anaconda3/lib/python3.7/site-packages/sqlalchemy/pool/impl.py", line 139, in _do_get
    self._dec_overflow()
  File "/Users/eiji/anaconda3/lib/python3.7/site-packages/sqlalchemy/util/langhelpers.py", line 68, in __exit__
    compat.reraise(exc_type, exc_value, exc_tb)
  File "/Users/eiji/anaconda3/lib/python3.7/site-packages/sqlalchemy/util/compat.py", line 153, in reraise
    raise value
  File "/Users/eiji/anaconda3/lib/python3.7/site-packages/sqlalchemy/pool/impl.py", line 136, in _do_get
    return self._create_connection()
  File "/Users/eiji/anaconda3/lib/python3.7/site-packages/sqlalchemy/pool/base.py", line 308, in _create_connection
    return _ConnectionRecord(self)
  File "/Users/eiji/anaconda3/lib/python3.7/site-packages/sqlalchemy/pool/base.py", line 437, in __init__
    self.__connect(first_connect_check=True)
  File "/Users/eiji/anaconda3/lib/python3.7/site-packages/sqlalchemy/pool/base.py", line 639, in __connect
    connection = pool._invoke_creator(self)
  File "/Users/eiji/anaconda3/lib/python3.7/site-packages/sqlalchemy/engine/strategies.py", line 114, in connect
    return dialect.connect(*cargs, **cparams)
  File "/Users/eiji/anaconda3/lib/python3.7/site-packages/sqlalchemy/engine/default.py", line 482, in connect
    return self.dbapi.connect(*cargs, **cparams)
  File "/Users/eiji/anaconda3/lib/python3.7/site-packages/psycopg2/__init__.py", line 126, in connect
    conn = _connect(dsn, connection_factory=connection_factory, **kwasync)
psycopg2.OperationalError: FATAL:  role "amy" does not exist


The above exception was the direct cause of the following exception:

Traceback (most recent call last):
  File "/Users/eiji/anaconda3/lib/python3.7/site-packages/flask/app.py", line 2311, in wsgi_app
    response = self.full_dispatch_request()
  File "/Users/eiji/anaconda3/lib/python3.7/site-packages/flask/app.py", line 1834, in full_dispatch_request
    rv = self.handle_user_exception(e)
  File "/Users/eiji/anaconda3/lib/python3.7/site-packages/flask/app.py", line 1737, in handle_user_exception
    reraise(exc_type, exc_value, tb)
  File "/Users/eiji/anaconda3/lib/python3.7/site-packages/flask/_compat.py", line 36, in reraise
    raise value
  File "/Users/eiji/anaconda3/lib/python3.7/site-packages/flask/app.py", line 1832, in full_dispatch_request
    rv = self.dispatch_request()
  File "/Users/eiji/anaconda3/lib/python3.7/site-packages/flask/app.py", line 1818, in dispatch_request
    return self.view_functions[rule.endpoint](**req.view_args)
  File "/Users/eiji/Desktop/class-demo/01_fyyur/projects/app.py", line 137, in venues
    )
  File "/Users/eiji/anaconda3/lib/python3.7/site-packages/sqlalchemy/orm/query.py", line 3211, in all
    return list(self)
  File "/Users/eiji/anaconda3/lib/python3.7/site-packages/sqlalchemy/orm/query.py", line 3367, in __iter__
    return self._execute_and_instances(context)
  File "/Users/eiji/anaconda3/lib/python3.7/site-packages/sqlalchemy/orm/query.py", line 3389, in _execute_and_instances
    querycontext, self._connection_from_session, close_with_result=True
  File "/Users/eiji/anaconda3/lib/python3.7/site-packages/sqlalchemy/orm/query.py", line 3404, in _get_bind_args
    mapper=self._bind_mapper(), clause=querycontext.statement, **kw
  File "/Users/eiji/anaconda3/lib/python3.7/site-packages/sqlalchemy/orm/query.py", line 3382, in _connection_from_session
    conn = self.session.connection(**kw)
  File "/Users/eiji/anaconda3/lib/python3.7/site-packages/sqlalchemy/orm/session.py", line 1124, in connection
    execution_options=execution_options,
  File "/Users/eiji/anaconda3/lib/python3.7/site-packages/sqlalchemy/orm/session.py", line 1130, in _connection_for_bind
    engine, execution_options
  File "/Users/eiji/anaconda3/lib/python3.7/site-packages/sqlalchemy/orm/session.py", line 431, in _connection_for_bind
    conn = bind._contextual_connect()
  File "/Users/eiji/anaconda3/lib/python3.7/site-packages/sqlalchemy/engine/base.py", line 2242, in _contextual_connect
    self._wrap_pool_connect(self.pool.connect, None),
  File "/Users/eiji/anaconda3/lib/python3.7/site-packages/sqlalchemy/engine/base.py", line 2280, in _wrap_pool_connect
    e, dialect, self
  File "/Users/eiji/anaconda3/lib/python3.7/site-packages/sqlalchemy/engine/base.py", line 1547, in _handle_dbapi_exception_noconnection
    util.raise_from_cause(sqlalchemy_exception, exc_info)
  File "/Users/eiji/anaconda3/lib/python3.7/site-packages/sqlalchemy/util/compat.py", line 398, in raise_from_cause
    reraise(type(exception), exception, tb=exc_tb, cause=cause)
  File "/Users/eiji/anaconda3/lib/python3.7/site-packages/sqlalchemy/util/compat.py", line 152, in reraise
    raise value.with_traceback(tb)
  File "/Users/eiji/anaconda3/lib/python3.7/site-packages/sqlalchemy/engine/base.py", line 2276, in _wrap_pool_connect
    return fn()
  File "/Users/eiji/anaconda3/lib/python3.7/site-packages/sqlalchemy/pool/base.py", line 363, in connect
    return _ConnectionFairy._checkout(self)
  File "/Users/eiji/anaconda3/lib/python3.7/site-packages/sqlalchemy/pool/base.py", line 760, in _checkout
    fairy = _ConnectionRecord.checkout(pool)
  File "/Users/eiji/anaconda3/lib/python3.7/site-packages/sqlalchemy/pool/base.py", line 492, in checkout
    rec = pool._do_get()
  File "/Users/eiji/anaconda3/lib/python3.7/site-packages/sqlalchemy/pool/impl.py", line 139, in _do_get
    self._dec_overflow()
  File "/Users/eiji/anaconda3/lib/python3.7/site-packages/sqlalchemy/util/langhelpers.py", line 68, in __exit__
    compat.reraise(exc_type, exc_value, exc_tb)
  File "/Users/eiji/anaconda3/lib/python3.7/site-packages/sqlalchemy/util/compat.py", line 153, in reraise
    raise value
  File "/Users/eiji/anaconda3/lib/python3.7/site-packages/sqlalchemy/pool/impl.py", line 136, in _do_get
    return self._create_connection()
  File "/Users/eiji/anaconda3/lib/python3.7/site-packages/sqlalchemy/pool/base.py", line 308, in _create_connection
    return _ConnectionRecord(self)
  File "/Users/eiji/anaconda3/lib/python3.7/site-packages/sqlalchemy/pool/base.py", line 437, in __init__
    self.__connect(first_connect_check=True)
  File "/Users/eiji/anaconda3/lib/python3.7/site-packages/sqlalchemy/pool/base.py", line 639, in __connect
    connection = pool._invoke_creator(self)
  File "/Users/eiji/anaconda3/lib/python3.7/site-packages/sqlalchemy/engine/strategies.py", line 114, in connect
    return dialect.connect(*cargs, **cparams)
  File "/Users/eiji/anaconda3/lib/python3.7/site-packages/sqlalchemy/engine/default.py", line 482, in connect
    return self.dbapi.connect(*cargs, **cparams)
  File "/Users/eiji/anaconda3/lib/python3.7/site-packages/psycopg2/__init__.py", line 126, in connect
    conn = _connect(dsn, connection_factory=connection_factory, **kwasync)
sqlalchemy.exc.OperationalError: (psycopg2.OperationalError) FATAL:  role "amy" does not exist

(Background on this error at: http://sqlalche.me/e/e3q8)
2020-01-05 17:14:34,812 ERROR: Exception on /venues [GET] [in /Users/eiji/anaconda3/lib/python3.7/site-packages/flask/app.py:1780]
Traceback (most recent call last):
  File "/Users/eiji/anaconda3/lib/python3.7/site-packages/sqlalchemy/engine/base.py", line 2276, in _wrap_pool_connect
    return fn()
  File "/Users/eiji/anaconda3/lib/python3.7/site-packages/sqlalchemy/pool/base.py", line 363, in connect
    return _ConnectionFairy._checkout(self)
  File "/Users/eiji/anaconda3/lib/python3.7/site-packages/sqlalchemy/pool/base.py", line 760, in _checkout
    fairy = _ConnectionRecord.checkout(pool)
  File "/Users/eiji/anaconda3/lib/python3.7/site-packages/sqlalchemy/pool/base.py", line 492, in checkout
    rec = pool._do_get()
  File "/Users/eiji/anaconda3/lib/python3.7/site-packages/sqlalchemy/pool/impl.py", line 139, in _do_get
    self._dec_overflow()
  File "/Users/eiji/anaconda3/lib/python3.7/site-packages/sqlalchemy/util/langhelpers.py", line 68, in __exit__
    compat.reraise(exc_type, exc_value, exc_tb)
  File "/Users/eiji/anaconda3/lib/python3.7/site-packages/sqlalchemy/util/compat.py", line 153, in reraise
    raise value
  File "/Users/eiji/anaconda3/lib/python3.7/site-packages/sqlalchemy/pool/impl.py", line 136, in _do_get
    return self._create_connection()
  File "/Users/eiji/anaconda3/lib/python3.7/site-packages/sqlalchemy/pool/base.py", line 308, in _create_connection
    return _ConnectionRecord(self)
  File "/Users/eiji/anaconda3/lib/python3.7/site-packages/sqlalchemy/pool/base.py", line 437, in __init__
    self.__connect(first_connect_check=True)
  File "/Users/eiji/anaconda3/lib/python3.7/site-packages/sqlalchemy/pool/base.py", line 639, in __connect
    connection = pool._invoke_creator(self)
  File "/Users/eiji/anaconda3/lib/python3.7/site-packages/sqlalchemy/engine/strategies.py", line 114, in connect
    return dialect.connect(*cargs, **cparams)
  File "/Users/eiji/anaconda3/lib/python3.7/site-packages/sqlalchemy/engine/default.py", line 482, in connect
    return self.dbapi.connect(*cargs, **cparams)
  File "/Users/eiji/anaconda3/lib/python3.7/site-packages/psycopg2/__init__.py", line 126, in connect
    conn = _connect(dsn, connection_factory=connection_factory, **kwasync)
psycopg2.OperationalError: FATAL:  role "amy" does not exist


The above exception was the direct cause of the following exception:

Traceback (most recent call last):
  File "/Users/eiji/anaconda3/lib/python3.7/site-packages/flask/app.py", line 2311, in wsgi_app
    response = self.full_dispatch_request()
  File "/Users/eiji/anaconda3/lib/python3.7/site-packages/flask/app.py", line 1834, in full_dispatch_request
    rv = self.handle_user_exception(e)
  File "/Users/eiji/anaconda3/lib/python3.7/site-packages/flask/app.py", line 1737, in handle_user_exception
    reraise(exc_type, exc_value, tb)
  File "/Users/eiji/anaconda3/lib/python3.7/site-packages/flask/_compat.py", line 36, in reraise
    raise value
  File "/Users/eiji/anaconda3/lib/python3.7/site-packages/flask/app.py", line 1832, in full_dispatch_request
    rv = self.dispatch_request()
  File "/Users/eiji/anaconda3/lib/python3.7/site-packages/flask/app.py", line 1818, in dispatch_request
    return self.view_functions[rule.endpoint](**req.view_args)
  File "/Users/eiji/Desktop/class-demo/01_fyyur/projects/app.py", line 137, in venues
    )
  File "/Users/eiji/anaconda3/lib/python3.7/site-packages/sqlalchemy/orm/query.py", line 3211, in all
    return list(self)
  File "/Users/eiji/anaconda3/lib/python3.7/site-packages/sqlalchemy/orm/query.py", line 3367, in __iter__
    return self._execute_and_instances(context)
  File "/Users/eiji/anaconda3/lib/python3.7/site-packages/sqlalchemy/orm/query.py", line 3389, in _execute_and_instances
    querycontext, self._connection_from_session, close_with_result=True
  File "/Users/eiji/anaconda3/lib/python3.7/site-packages/sqlalchemy/orm/query.py", line 3404, in _get_bind_args
    mapper=self._bind_mapper(), clause=querycontext.statement, **kw
  File "/Users/eiji/anaconda3/lib/python3.7/site-packages/sqlalchemy/orm/query.py", line 3382, in _connection_from_session
    conn = self.session.connection(**kw)
  File "/Users/eiji/anaconda3/lib/python3.7/site-packages/sqlalchemy/orm/session.py", line 1124, in connection
    execution_options=execution_options,
  File "/Users/eiji/anaconda3/lib/python3.7/site-packages/sqlalchemy/orm/session.py", line 1130, in _connection_for_bind
    engine, execution_options
  File "/Users/eiji/anaconda3/lib/python3.7/site-packages/sqlalchemy/orm/session.py", line 431, in _connection_for_bind
    conn = bind._contextual_connect()
  File "/Users/eiji/anaconda3/lib/python3.7/site-packages/sqlalchemy/engine/base.py", line 2242, in _contextual_connect
    self._wrap_pool_connect(self.pool.connect, None),
  File "/Users/eiji/anaconda3/lib/python3.7/site-packages/sqlalchemy/engine/base.py", line 2280, in _wrap_pool_connect
    e, dialect, self
  File "/Users/eiji/anaconda3/lib/python3.7/site-packages/sqlalchemy/engine/base.py", line 1547, in _handle_dbapi_exception_noconnection
    util.raise_from_cause(sqlalchemy_exception, exc_info)
  File "/Users/eiji/anaconda3/lib/python3.7/site-packages/sqlalchemy/util/compat.py", line 398, in raise_from_cause
    reraise(type(exception), exception, tb=exc_tb, cause=cause)
  File "/Users/eiji/anaconda3/lib/python3.7/site-packages/sqlalchemy/util/compat.py", line 152, in reraise
    raise value.with_traceback(tb)
  File "/Users/eiji/anaconda3/lib/python3.7/site-packages/sqlalchemy/engine/base.py", line 2276, in _wrap_pool_connect
    return fn()
  File "/Users/eiji/anaconda3/lib/python3.7/site-packages/sqlalchemy/pool/base.py", line 363, in connect
    return _ConnectionFairy._checkout(self)
  File "/Users/eiji/anaconda3/lib/python3.7/site-packages/sqlalchemy/pool/base.py", line 760, in _checkout
    fairy = _ConnectionRecord.checkout(pool)
  File "/Users/eiji/anaconda3/lib/python3.7/site-packages/sqlalchemy/pool/base.py", line 492, in checkout
    rec = pool._do_get()
  File "/Users/eiji/anaconda3/lib/python3.7/site-packages/sqlalchemy/pool/impl.py", line 139, in _do_get
    self._dec_overflow()
  File "/Users/eiji/anaconda3/lib/python3.7/site-packages/sqlalchemy/util/langhelpers.py", line 68, in __exit__
    compat.reraise(exc_type, exc_value, exc_tb)
  File "/Users/eiji/anaconda3/lib/python3.7/site-packages/sqlalchemy/util/compat.py", line 153, in reraise
    raise value
  File "/Users/eiji/anaconda3/lib/python3.7/site-packages/sqlalchemy/pool/impl.py", line 136, in _do_get
    return self._create_connection()
  File "/Users/eiji/anaconda3/lib/python3.7/site-packages/sqlalchemy/pool/base.py", line 308, in _create_connection
    return _ConnectionRecord(self)
  File "/Users/eiji/anaconda3/lib/python3.7/site-packages/sqlalchemy/pool/base.py", line 437, in __init__
    self.__connect(first_connect_check=True)
  File "/Users/eiji/anaconda3/lib/python3.7/site-packages/sqlalchemy/pool/base.py", line 639, in __connect
    connection = pool._invoke_creator(self)
  File "/Users/eiji/anaconda3/lib/python3.7/site-packages/sqlalchemy/engine/strategies.py", line 114, in connect
    return dialect.connect(*cargs, **cparams)
  File "/Users/eiji/anaconda3/lib/python3.7/site-packages/sqlalchemy/engine/default.py", line 482, in connect
    return self.dbapi.connect(*cargs, **cparams)
  File "/Users/eiji/anaconda3/lib/python3.7/site-packages/psycopg2/__init__.py", line 126, in connect
    conn = _connect(dsn, connection_factory=connection_factory, **kwasync)
sqlalchemy.exc.OperationalError: (psycopg2.OperationalError) FATAL:  role "amy" does not exist

(Background on this error at: http://sqlalche.me/e/e3q8)
2020-01-05 17:14:39,498 ERROR: Exception on /venues [GET] [in /Users/eiji/anaconda3/lib/python3.7/site-packages/flask/app.py:1780]
Traceback (most recent call last):
  File "/Users/eiji/anaconda3/lib/python3.7/site-packages/sqlalchemy/engine/base.py", line 2276, in _wrap_pool_connect
    return fn()
  File "/Users/eiji/anaconda3/lib/python3.7/site-packages/sqlalchemy/pool/base.py", line 363, in connect
    return _ConnectionFairy._checkout(self)
  File "/Users/eiji/anaconda3/lib/python3.7/site-packages/sqlalchemy/pool/base.py", line 760, in _checkout
    fairy = _ConnectionRecord.checkout(pool)
  File "/Users/eiji/anaconda3/lib/python3.7/site-packages/sqlalchemy/pool/base.py", line 492, in checkout
    rec = pool._do_get()
  File "/Users/eiji/anaconda3/lib/python3.7/site-packages/sqlalchemy/pool/impl.py", line 139, in _do_get
    self._dec_overflow()
  File "/Users/eiji/anaconda3/lib/python3.7/site-packages/sqlalchemy/util/langhelpers.py", line 68, in __exit__
    compat.reraise(exc_type, exc_value, exc_tb)
  File "/Users/eiji/anaconda3/lib/python3.7/site-packages/sqlalchemy/util/compat.py", line 153, in reraise
    raise value
  File "/Users/eiji/anaconda3/lib/python3.7/site-packages/sqlalchemy/pool/impl.py", line 136, in _do_get
    return self._create_connection()
  File "/Users/eiji/anaconda3/lib/python3.7/site-packages/sqlalchemy/pool/base.py", line 308, in _create_connection
    return _ConnectionRecord(self)
  File "/Users/eiji/anaconda3/lib/python3.7/site-packages/sqlalchemy/pool/base.py", line 437, in __init__
    self.__connect(first_connect_check=True)
  File "/Users/eiji/anaconda3/lib/python3.7/site-packages/sqlalchemy/pool/base.py", line 639, in __connect
    connection = pool._invoke_creator(self)
  File "/Users/eiji/anaconda3/lib/python3.7/site-packages/sqlalchemy/engine/strategies.py", line 114, in connect
    return dialect.connect(*cargs, **cparams)
  File "/Users/eiji/anaconda3/lib/python3.7/site-packages/sqlalchemy/engine/default.py", line 482, in connect
    return self.dbapi.connect(*cargs, **cparams)
  File "/Users/eiji/anaconda3/lib/python3.7/site-packages/psycopg2/__init__.py", line 126, in connect
    conn = _connect(dsn, connection_factory=connection_factory, **kwasync)
psycopg2.OperationalError: FATAL:  role "amy" does not exist


The above exception was the direct cause of the following exception:

Traceback (most recent call last):
  File "/Users/eiji/anaconda3/lib/python3.7/site-packages/flask/app.py", line 2311, in wsgi_app
    response = self.full_dispatch_request()
  File "/Users/eiji/anaconda3/lib/python3.7/site-packages/flask/app.py", line 1834, in full_dispatch_request
    rv = self.handle_user_exception(e)
  File "/Users/eiji/anaconda3/lib/python3.7/site-packages/flask/app.py", line 1737, in handle_user_exception
    reraise(exc_type, exc_value, tb)
  File "/Users/eiji/anaconda3/lib/python3.7/site-packages/flask/_compat.py", line 36, in reraise
    raise value
  File "/Users/eiji/anaconda3/lib/python3.7/site-packages/flask/app.py", line 1832, in full_dispatch_request
    rv = self.dispatch_request()
  File "/Users/eiji/anaconda3/lib/python3.7/site-packages/flask/app.py", line 1818, in dispatch_request
    return self.view_functions[rule.endpoint](**req.view_args)
  File "/Users/eiji/Desktop/class-demo/01_fyyur/projects/app.py", line 137, in venues
    )
  File "/Users/eiji/anaconda3/lib/python3.7/site-packages/sqlalchemy/orm/query.py", line 3211, in all
    return list(self)
  File "/Users/eiji/anaconda3/lib/python3.7/site-packages/sqlalchemy/orm/query.py", line 3367, in __iter__
    return self._execute_and_instances(context)
  File "/Users/eiji/anaconda3/lib/python3.7/site-packages/sqlalchemy/orm/query.py", line 3389, in _execute_and_instances
    querycontext, self._connection_from_session, close_with_result=True
  File "/Users/eiji/anaconda3/lib/python3.7/site-packages/sqlalchemy/orm/query.py", line 3404, in _get_bind_args
    mapper=self._bind_mapper(), clause=querycontext.statement, **kw
  File "/Users/eiji/anaconda3/lib/python3.7/site-packages/sqlalchemy/orm/query.py", line 3382, in _connection_from_session
    conn = self.session.connection(**kw)
  File "/Users/eiji/anaconda3/lib/python3.7/site-packages/sqlalchemy/orm/session.py", line 1124, in connection
    execution_options=execution_options,
  File "/Users/eiji/anaconda3/lib/python3.7/site-packages/sqlalchemy/orm/session.py", line 1130, in _connection_for_bind
    engine, execution_options
  File "/Users/eiji/anaconda3/lib/python3.7/site-packages/sqlalchemy/orm/session.py", line 431, in _connection_for_bind
    conn = bind._contextual_connect()
  File "/Users/eiji/anaconda3/lib/python3.7/site-packages/sqlalchemy/engine/base.py", line 2242, in _contextual_connect
    self._wrap_pool_connect(self.pool.connect, None),
  File "/Users/eiji/anaconda3/lib/python3.7/site-packages/sqlalchemy/engine/base.py", line 2280, in _wrap_pool_connect
    e, dialect, self
  File "/Users/eiji/anaconda3/lib/python3.7/site-packages/sqlalchemy/engine/base.py", line 1547, in _handle_dbapi_exception_noconnection
    util.raise_from_cause(sqlalchemy_exception, exc_info)
  File "/Users/eiji/anaconda3/lib/python3.7/site-packages/sqlalchemy/util/compat.py", line 398, in raise_from_cause
    reraise(type(exception), exception, tb=exc_tb, cause=cause)
  File "/Users/eiji/anaconda3/lib/python3.7/site-packages/sqlalchemy/util/compat.py", line 152, in reraise
    raise value.with_traceback(tb)
  File "/Users/eiji/anaconda3/lib/python3.7/site-packages/sqlalchemy/engine/base.py", line 2276, in _wrap_pool_connect
    return fn()
  File "/Users/eiji/anaconda3/lib/python3.7/site-packages/sqlalchemy/pool/base.py", line 363, in connect
    return _ConnectionFairy._checkout(self)
  File "/Users/eiji/anaconda3/lib/python3.7/site-packages/sqlalchemy/pool/base.py", line 760, in _checkout
    fairy = _ConnectionRecord.checkout(pool)
  File "/Users/eiji/anaconda3/lib/python3.7/site-packages/sqlalchemy/pool/base.py", line 492, in checkout
    rec = pool._do_get()
  File "/Users/eiji/anaconda3/lib/python3.7/site-packages/sqlalchemy/pool/impl.py", line 139, in _do_get
    self._dec_overflow()
  File "/Users/eiji/anaconda3/lib/python3.7/site-packages/sqlalchemy/util/langhelpers.py", line 68, in __exit__
    compat.reraise(exc_type, exc_value, exc_tb)
  File "/Users/eiji/anaconda3/lib/python3.7/site-packages/sqlalchemy/util/compat.py", line 153, in reraise
    raise value
  File "/Users/eiji/anaconda3/lib/python3.7/site-packages/sqlalchemy/pool/impl.py", line 136, in _do_get
    return self._create_connection()
  File "/Users/eiji/anaconda3/lib/python3.7/site-packages/sqlalchemy/pool/base.py", line 308, in _create_connection
    return _ConnectionRecord(self)
  File "/Users/eiji/anaconda3/lib/python3.7/site-packages/sqlalchemy/pool/base.py", line 437, in __init__
    self.__connect(first_connect_check=True)
  File "/Users/eiji/anaconda3/lib/python3.7/site-packages/sqlalchemy/pool/base.py", line 639, in __connect
    connection = pool._invoke_creator(self)
  File "/Users/eiji/anaconda3/lib/python3.7/site-packages/sqlalchemy/engine/strategies.py", line 114, in connect
    return dialect.connect(*cargs, **cparams)
  File "/Users/eiji/anaconda3/lib/python3.7/site-packages/sqlalchemy/engine/default.py", line 482, in connect
    return self.dbapi.connect(*cargs, **cparams)
  File "/Users/eiji/anaconda3/lib/python3.7/site-packages/psycopg2/__init__.py", line 126, in connect
    conn = _connect(dsn, connection_factory=connection_factory, **kwasync)
sqlalchemy.exc.OperationalError: (psycopg2.OperationalError) FATAL:  role "amy" does not exist

(Background on this error at: http://sqlalche.me/e/e3q8)
2020-01-05 17:15:18,636 ERROR: Exception on /venues [GET] [in /Users/eiji/anaconda3/lib/python3.7/site-packages/flask/app.py:1780]
Traceback (most recent call last):
  File "/Users/eiji/anaconda3/lib/python3.7/site-packages/sqlalchemy/engine/base.py", line 2276, in _wrap_pool_connect
    return fn()
  File "/Users/eiji/anaconda3/lib/python3.7/site-packages/sqlalchemy/pool/base.py", line 363, in connect
    return _ConnectionFairy._checkout(self)
  File "/Users/eiji/anaconda3/lib/python3.7/site-packages/sqlalchemy/pool/base.py", line 760, in _checkout
    fairy = _ConnectionRecord.checkout(pool)
  File "/Users/eiji/anaconda3/lib/python3.7/site-packages/sqlalchemy/pool/base.py", line 492, in checkout
    rec = pool._do_get()
  File "/Users/eiji/anaconda3/lib/python3.7/site-packages/sqlalchemy/pool/impl.py", line 139, in _do_get
    self._dec_overflow()
  File "/Users/eiji/anaconda3/lib/python3.7/site-packages/sqlalchemy/util/langhelpers.py", line 68, in __exit__
    compat.reraise(exc_type, exc_value, exc_tb)
  File "/Users/eiji/anaconda3/lib/python3.7/site-packages/sqlalchemy/util/compat.py", line 153, in reraise
    raise value
  File "/Users/eiji/anaconda3/lib/python3.7/site-packages/sqlalchemy/pool/impl.py", line 136, in _do_get
    return self._create_connection()
  File "/Users/eiji/anaconda3/lib/python3.7/site-packages/sqlalchemy/pool/base.py", line 308, in _create_connection
    return _ConnectionRecord(self)
  File "/Users/eiji/anaconda3/lib/python3.7/site-packages/sqlalchemy/pool/base.py", line 437, in __init__
    self.__connect(first_connect_check=True)
  File "/Users/eiji/anaconda3/lib/python3.7/site-packages/sqlalchemy/pool/base.py", line 639, in __connect
    connection = pool._invoke_creator(self)
  File "/Users/eiji/anaconda3/lib/python3.7/site-packages/sqlalchemy/engine/strategies.py", line 114, in connect
    return dialect.connect(*cargs, **cparams)
  File "/Users/eiji/anaconda3/lib/python3.7/site-packages/sqlalchemy/engine/default.py", line 482, in connect
    return self.dbapi.connect(*cargs, **cparams)
  File "/Users/eiji/anaconda3/lib/python3.7/site-packages/psycopg2/__init__.py", line 126, in connect
    conn = _connect(dsn, connection_factory=connection_factory, **kwasync)
psycopg2.OperationalError: FATAL:  role "amy" does not exist


The above exception was the direct cause of the following exception:

Traceback (most recent call last):
  File "/Users/eiji/anaconda3/lib/python3.7/site-packages/flask/app.py", line 2311, in wsgi_app
    response = self.full_dispatch_request()
  File "/Users/eiji/anaconda3/lib/python3.7/site-packages/flask/app.py", line 1834, in full_dispatch_request
    rv = self.handle_user_exception(e)
  File "/Users/eiji/anaconda3/lib/python3.7/site-packages/flask/app.py", line 1737, in handle_user_exception
    reraise(exc_type, exc_value, tb)
  File "/Users/eiji/anaconda3/lib/python3.7/site-packages/flask/_compat.py", line 36, in reraise
    raise value
  File "/Users/eiji/anaconda3/lib/python3.7/site-packages/flask/app.py", line 1832, in full_dispatch_request
    rv = self.dispatch_request()
  File "/Users/eiji/anaconda3/lib/python3.7/site-packages/flask/app.py", line 1818, in dispatch_request
    return self.view_functions[rule.endpoint](**req.view_args)
  File "/Users/eiji/Desktop/class-demo/01_fyyur/projects/app.py", line 137, in venues
    )
  File "/Users/eiji/anaconda3/lib/python3.7/site-packages/sqlalchemy/orm/query.py", line 3211, in all
    return list(self)
  File "/Users/eiji/anaconda3/lib/python3.7/site-packages/sqlalchemy/orm/query.py", line 3367, in __iter__
    return self._execute_and_instances(context)
  File "/Users/eiji/anaconda3/lib/python3.7/site-packages/sqlalchemy/orm/query.py", line 3389, in _execute_and_instances
    querycontext, self._connection_from_session, close_with_result=True
  File "/Users/eiji/anaconda3/lib/python3.7/site-packages/sqlalchemy/orm/query.py", line 3404, in _get_bind_args
    mapper=self._bind_mapper(), clause=querycontext.statement, **kw
  File "/Users/eiji/anaconda3/lib/python3.7/site-packages/sqlalchemy/orm/query.py", line 3382, in _connection_from_session
    conn = self.session.connection(**kw)
  File "/Users/eiji/anaconda3/lib/python3.7/site-packages/sqlalchemy/orm/session.py", line 1124, in connection
    execution_options=execution_options,
  File "/Users/eiji/anaconda3/lib/python3.7/site-packages/sqlalchemy/orm/session.py", line 1130, in _connection_for_bind
    engine, execution_options
  File "/Users/eiji/anaconda3/lib/python3.7/site-packages/sqlalchemy/orm/session.py", line 431, in _connection_for_bind
    conn = bind._contextual_connect()
  File "/Users/eiji/anaconda3/lib/python3.7/site-packages/sqlalchemy/engine/base.py", line 2242, in _contextual_connect
    self._wrap_pool_connect(self.pool.connect, None),
  File "/Users/eiji/anaconda3/lib/python3.7/site-packages/sqlalchemy/engine/base.py", line 2280, in _wrap_pool_connect
    e, dialect, self
  File "/Users/eiji/anaconda3/lib/python3.7/site-packages/sqlalchemy/engine/base.py", line 1547, in _handle_dbapi_exception_noconnection
    util.raise_from_cause(sqlalchemy_exception, exc_info)
  File "/Users/eiji/anaconda3/lib/python3.7/site-packages/sqlalchemy/util/compat.py", line 398, in raise_from_cause
    reraise(type(exception), exception, tb=exc_tb, cause=cause)
  File "/Users/eiji/anaconda3/lib/python3.7/site-packages/sqlalchemy/util/compat.py", line 152, in reraise
    raise value.with_traceback(tb)
  File "/Users/eiji/anaconda3/lib/python3.7/site-packages/sqlalchemy/engine/base.py", line 2276, in _wrap_pool_connect
    return fn()
  File "/Users/eiji/anaconda3/lib/python3.7/site-packages/sqlalchemy/pool/base.py", line 363, in connect
    return _ConnectionFairy._checkout(self)
  File "/Users/eiji/anaconda3/lib/python3.7/site-packages/sqlalchemy/pool/base.py", line 760, in _checkout
    fairy = _ConnectionRecord.checkout(pool)
  File "/Users/eiji/anaconda3/lib/python3.7/site-packages/sqlalchemy/pool/base.py", line 492, in checkout
    rec = pool._do_get()
  File "/Users/eiji/anaconda3/lib/python3.7/site-packages/sqlalchemy/pool/impl.py", line 139, in _do_get
    self._dec_overflow()
  File "/Users/eiji/anaconda3/lib/python3.7/site-packages/sqlalchemy/util/langhelpers.py", line 68, in __exit__
    compat.reraise(exc_type, exc_value, exc_tb)
  File "/Users/eiji/anaconda3/lib/python3.7/site-packages/sqlalchemy/util/compat.py", line 153, in reraise
    raise value
  File "/Users/eiji/anaconda3/lib/python3.7/site-packages/sqlalchemy/pool/impl.py", line 136, in _do_get
    return self._create_connection()
  File "/Users/eiji/anaconda3/lib/python3.7/site-packages/sqlalchemy/pool/base.py", line 308, in _create_connection
    return _ConnectionRecord(self)
  File "/Users/eiji/anaconda3/lib/python3.7/site-packages/sqlalchemy/pool/base.py", line 437, in __init__
    self.__connect(first_connect_check=True)
  File "/Users/eiji/anaconda3/lib/python3.7/site-packages/sqlalchemy/pool/base.py", line 639, in __connect
    connection = pool._invoke_creator(self)
  File "/Users/eiji/anaconda3/lib/python3.7/site-packages/sqlalchemy/engine/strategies.py", line 114, in connect
    return dialect.connect(*cargs, **cparams)
  File "/Users/eiji/anaconda3/lib/python3.7/site-packages/sqlalchemy/engine/default.py", line 482, in connect
    return self.dbapi.connect(*cargs, **cparams)
  File "/Users/eiji/anaconda3/lib/python3.7/site-packages/psycopg2/__init__.py", line 126, in connect
    conn = _connect(dsn, connection_factory=connection_factory, **kwasync)
sqlalchemy.exc.OperationalError: (psycopg2.OperationalError) FATAL:  role "amy" does not exist

(Background on this error at: http://sqlalche.me/e/e3q8)
